Workbook
Name _age2: 資料輸入區!$L$39
Name _Sex2: 資料輸入區!$K$70
Name Age: 資料輸入區!$I$10
Name Corridor: 險種基本資料!$A$36:$D$146
Name CSWD: 險種基本資料!$G$14
Name CurrList: 險種基本資料!$A$30:$A$33
Name CYPremium: 資料輸入區!$N$23
Name dangerRate: 險種基本資料!$D$2
Name DecareRate: 資料輸入區!$E$20
Name DVAC: 險種基本資料!$G$15
Name factor_key: 險種基本資料!$C$23:$E$24
Name factor_key_3: #REF!
Name firstpay: 資料輸入區!$N$20
Name FYPremium: 資料輸入區!$N$22
Name GP: 險種基本資料!$F$24
Name GP_3: #REF!
Name isRec: 資料輸入區!$M$51
Name ListDIVOPT01: 險種基本資料!$F$13:$F$14
Name ListDIVOPT02: 險種基本資料!$G$14:$G$16
Name ListDIVOPT02_: 險種基本資料!$G$13:$G$16
Name ListSex: 資料輸入區!$B$41:$B$42
Name LoanP: 資料輸入區!$E$28
Name MinSA: 險種基本資料!$F$28
Name PayYear: 資料輸入區!$D$12
Name PDRate: 資料輸入區!$E$21
Name PMST: 險種基本資料!$G$13
Name Premium: 險種基本資料!$AO$4
Name PremMuti: 險種基本資料!$B$18
Name PUAD: 險種基本資料!$G$16
Name PUAYear: 險種基本資料!$B$16
Name RoundNo: 險種基本資料!$B$15
Name SA: 資料輸入區!$N$12
Name SA_3: 資料輸入區!$O$12
Name SA_3C: 資料輸入區!$U$12
Name SameOwner: 資料輸入區!$G$5
Name Sex: 資料輸入區!$G$10
Name UNIT: 險種基本資料!$B$13
Name UNIT3: #REF!
Name UVUNIT: 險種基本資料!$B$14
Name UVUNIT3: #REF!
Name ZDIVOPT01: 資料輸入區!$E$18
Name ZDIVOPT02: 資料輸入區!$E$19
Name 期繳: 資料輸入區!$B$36:$B$39
Name 躉繳: 資料輸入區!$B$40

Sheet 資料輸入區
Q1: EBKD6UD411501380 115.01版
B2: 凱基人壽美利成臻美元利率變動型終身壽險－定期給付型
B4: ◎請於"反白"儲存格填入相關基本資料
B5: 要保人／被保險人／實際繳交保費之人相同 | G5: 是 | I5: =IF(AND(PayYear=1,LoanP="是"),IF(SameOwner="是","",IF(AND(Sex=G32,E11=E33,G11=G33,I11=I33),"","※要保人與被保險人須為同一人。")),"")
I6: =IF(M51,IF(H53,"※"&G53,"")&I53&IF(H54,G54,"")&I54&IF(H55,G55,"")&"保險年齡達六十五歲(含)以上，需配合進行銷售過程錄音，並請填寫下方『高齡錄音相關資料』。","") -> ※要保人、被保人、實際繳交保費之人保險年齡達六十五歲(含)以上，需配合進行銷售過程錄音，並請填寫下方『高齡錄音相關資料』。
A7: =IF(M48,IF(L30<20,"要保人未滿二十足歲，被保險人或實際繳交保費之人保險年齡達七十歲(含)以上，要保人、被保險人及要保人之『所有』法定代理人(父及母)需配合進行銷售過程錄音。","要保人或被保險人或實際繳交保費之人保險年齡若達七十歲(含)以上，要保人需配合進行銷售過程錄音。"),"")
B8: 被保險人基本資料與壽險購買條件設定 | M8: 訊息反應區
B9: ◎請於"反白"儲存格填入相關基本資料 | I9: 單位：美元 | P9: 單位：美元
B10: 1.姓名 | D10: AAA | F10: 性別 | G10: 男性 | H10: 保險年齡 | I10: =IF(OR(H37<0,H39<VLOOKUP(PayYear,險種基本資料!B2:I11,5,FALSE),H39>VLOOKUP(PayYear,險種基本資料!B2:I11,6,FALSE)),"NA",H39) -> 71 | J10: 歲 | N10: 美利成臻 | O10: 美好加在 | R10: 合計保費
B11: 2.生日 | D11: 民國 | E11: 44 | F11: 年 | G11: 1 | H11: 月 | I11: 23 | J11: 日出生 | M11: 保險年齡 | N11: =I10 -> 71 | O11: =IF(E25="不附加","-",IF(G25<>"","NA",_age2)) -> 71 | P11: 歲 | U11: SA_3C
B12: 3.繳費年期 | D12: =VLOOKUP(E12,險種基本資料!A2:B11,2,FALSE) -> 1 | E12: 躉 | F12: =IF(PayYear=1,"繳","年") -> 繳 | G12: =IF(F43<=10,"※假設試算日為生效日之年齡，再過"&F43&"天保險年齡加1歲。","") | M12: 投保金額 | N12: =IF(N11="NA","-",IF(M37,險種基本資料!AO3,"-")) -> 3701867 | O12: =IF(OR(SA="-",E25="不附加"),"-",IF(F25,"-",T12)) -> 0 | P12: 元 | S12: 豁免 保額 | T12: =IF(E25="附加",ROUND(ROUND(N14*(1-N15-N18-IF(N16>=1%,N16-1%,N16)),3),0),0) -> 0 | U12: =ROUND(SA_3/VLOOKUP(E13,B36:D39,3,FALSE),0) -> #N/A
B13: 4.繳別 | E13: 躉 | F13: 繳 | G13: =IF(OR(E11<>G48,G11<>H48,I11<>I48),"輸入生日有誤，請重新輸入",IF(OR(H37<0,H39<險種基本資料!D28,H39>險種基本資料!E28),"◎投保年齡限制為"&險種基本資料!D28&"~"&險種基本資料!E28&"歲，請重新輸入！",IF(NOT(M38),"請選擇正確繳別",""))) | M13: =IF(PayYear=1,"(1)每單位(1萬)躉繳表訂費率","(1)每單位(1萬)年繳表訂費率") -> (1)每單位(1萬)躉繳表訂費率 | N13: =IF(M37,GP,"-") -> 7714 | O13: =IF(OR(SA="-",E25="不附加"),"-",IF(F25,"-",GP_3/10)) -> #REF! | P13: 元 | S13: 費率 | T13: =IF(_age2="NA","-",GP_3/10) -> #REF!
B14: 5.計算方式 | E14: 保額 | G14: =IF(E14="保費","此欄位為試算保費金額，實際繳交保費應以試算表上所載首期保險費金額為準。","") | M14: (2)原始總保費=(1)*(保額÷單位)*繳別率(四捨五入) | N14: =IF(M37,ROUND(ROUND(ROUNDDOWN(ROUND(SA*UNIT/UVUNIT*GP,3),2)*VLOOKUP(E13,B36:D40,3,FALSE),3),0),"-") -> 2855620 | O14: =IF(OR(SA="-",E25="不附加"),"-",IF(F25,"-",T14)) -> #REF! | P14: 元 | R14: =SUM(N14:O14) -> #REF! | S14: 豁免 原始保費 | T14: =ROUND(ROUND(ROUNDDOWN(ROUND(T12*UNIT3/UVUNIT3*T13,3),2),3),0) -> #REF!
B15: =IF(E14="保額","6.保險金額","6."& "預計"&IF(PayYear=1,E13,"年")&"繳保費") -> 6.保險金額 | E15: 3701867 | F15: 元 | G15: =IF(險種基本資料!AO3<險種基本資料!F28,"最低投保金額為"&TEXT(險種基本資料!F28,"###,###,##0")&"元，請重新輸入！",IF(險種基本資料!AO3>險種基本資料!G28,"最高投保金額為"&TEXT(險種基本資料!G28,"###,###,##0")&"元，請重新輸入！",IF(AND(H37<15,險種基本資料!G24>險種基本資料!F19),"※未滿十五足歲其個人累計壽險危險保額最高限新台幣1,000萬元。",""))) | M15: (3)高保費費率折減 | N15: =IF(N11="NA","-",險種基本資料!C28) -> 0.07 | O15: -
B16: 7.首期繳費方式 | E16: 金融機構轉帳 | G16: =IF(AND($D$12=6,$E$15="集彙"),"六年期不適用集體彙繳折減優惠，請重新選擇繳費方式!",IF(PayYear = 1,"躉繳不提供保費折減",IF(E16="-","請選擇繳費方式",""))) -> 躉繳不提供保費折減 | M16: =IF(PayYear=1,"(4)躉繳保險費(2)*【1-(3)】","(4)首期"&E16&"費率折減") -> (4)躉繳保險費(2)*【1-(3)】 | N16: =IF(PayYear=1,TEXT(ROUND(ROUND(N14*(1-N15),3),0),"#,##0"),VLOOKUP(E16,E44:H47,2,FALSE)) -> 2,655,727 | P16: =IF(PayYear=1,"元","") -> 元 | S16: =VLOOKUP(E17,G44:H46,2,FALSE) -> 0
B17: 8.續期繳費方式 | E17: 金融機構轉帳 | G17: =IF(PayYear = 1,"躉繳不適用此選項",IF(E17="-","請選擇繳費方式","")) -> 躉繳不適用此選項 | M17: =IF(PayYear = 1,"實際繳交保費","(5)續期"&E17&"費率折減") -> 實際繳交保費 | N17: =IF(PayYear = 1,TEXT(IF(M37,IF(VLOOKUP(E13,B36:C40,2,FALSE)=12,2,1)*ROUND(ROUND(N14*(1-N18),3),0),"-"),"#,##0"),VLOOKUP(E17,G44:H46,2,FALSE)) -> 2,655,727 | S17: =IF(N11="NA","-",N15+IF(PayYear=1,0,N16)) -> 0.07
B18: 9.第一保單年度至第六保單年度增值回饋分享金給付方式 | E18: 以繳清保險方式增加保險金額 | G18: =IF($E$18=PMST,"繳費期間抵繳應繳保險費，繳費期滿以繳清保險方式增加保險金額","") | M18: (6)首期合計費率折減=(3)+(4) | N18: =IF(N11="NA","-",N15+IF(PayYear=1,0,N16)) -> 0.07 | O18: =IF(E25="不附加","-",N16) -> 2,655,727 | S18: =IF(N11="NA","-",N15+S16) -> 0.07
B19: =IF(PayYear=1,"7.增值回饋分享金給付方式","10.第七保單年度起增值回饋分享金給付方式") -> 7.增值回饋分享金給付方式 | E19: 以繳清保險方式增加保險金額 | G19: =IF(資料輸入區!I10<16,"※被保險人保險年齡到達十六歲之保單週年日時，其增值回饋分享金請參照保單條款。"," ") | M19: =IF(PayYear=1,"(4)躉繳保險費(2)*【1-(3)】","(7)續期合計費率折減=(3)+(5)") -> (4)躉繳保險費(2)*【1-(3)】 | N19: =IF(N11="NA","-",IF(PayYear=1,TEXT(ROUND(ROUND(N14*(1-N15),3),0),"#,##0"),N15+N17)) -> 2,655,727 | O19: =IF(E25="不附加","-",N17) -> 2,655,727 | P19: =IF(PayYear=1,"元","") -> 元
B20: 宣告利率(假設值) | E20: 4.35 | F20: % | G20: ※使用本試算表請確認宣告利率 | M20: =IF(PayYear=1,"實際繳交保費","(8)"&IF(N16>0,"扣除"&E16&"費率折減後，","")&"首期"&E13&"繳保險費=(2)*【1-"&IF(PayYear=1,"(5)","(6)")&"】(四捨五入)"&IF(E13="月","*2","")) -> 實際繳交保費 | N20: =IF(M37,IF(VLOOKUP(E13,B36:C40,2,FALSE)=12,2,1)*ROUND(ROUND(N14*(1-N18),3),0),"-") -> 2655727 | O20: =IF(OR(SA="-",E25="不附加"),"-",IF(F25,"-",T20)) -> #N/A | P20: 元 | R20: =SUM(N20:O20) -> #N/A | S20: 首期保費 | T20: =IF(VLOOKUP(E13,B36:C39,2,FALSE)=12,2,1)*ROUND(ROUND(T13*(1-P18),3),0) -> #N/A
B21: 預定利率 | E21: =險種基本資料!A28 -> 1.75 | F21: % | M21: =IF(PayYear=1,"","(9)"&IF(N17>0,"扣除"&E17&"費率折減後，","")&"續期"&E13&"繳保險費=(2)*【1-(7)】(四捨五入)") | N21: =IF(M37,ROUND(ROUND(N14*(1-N19),3),0),"-") -> -7583744280120 | O21: =IF(OR(SA="-",E25="不附加"),"-",IF(F25,"-",T21)) -> #REF! | P21: 元 | R21: =SUM(N21:O21) -> #REF! | S21: 續期保費 | T21: =ROUND(ROUND(T13*(1-P19),3),0) -> #REF!
B22: 是否超過體檢額度 | E22: =IF(SA="-","-",IF(SA<=險種基本資料!I24,"免體檢 （詳警語）","需體檢")) -> 需體檢 | F22: =IF(SA="-","","※【主約保險金額】若超過上限"&TEXT(險種基本資料!I24,"#,##0")&"元則需體檢") -> ※【主約保險金額】若超過上限500,000元則需體檢 | M22: ="(10)首年實繳保險費=(8)*1+(9)*"&(VLOOKUP(E13,B36:C40,2,FALSE)-IF(E13="月",2,1)) -> (10)首年實繳保險費=(8)*1+(9)*0 | N22: =IF(M37,N20+(VLOOKUP(E13,B36:C40,2,FALSE)-IF(VLOOKUP(E13,B36:C40,2,FALSE)=12,2,1))*N21,"-") -> 2655727 | O22: =IF(OR(SA="-",E25="不附加"),"-",IF(F25,"-",O20+O21*(VLOOKUP(E13,B36:C39,2,FALSE)-IF(VLOOKUP(E13,B36:C39,2,FALSE)=12,2,1)))) -> #N/A | P22: 元
M23: (11)續年實繳保險費=(9)*繳費次數 | N23: =IF(M37,VLOOKUP(E13,B36:C40,2,FALSE)*N21,"-") -> -7583744280120 | O23: =IF(OR(SA="-",E25="不附加"),"-",IF(F25,"-",O21*VLOOKUP(E13,B36:C39,2,FALSE))) -> #REF! | P23: 元
M24: =PayYear&"年總保費" -> 1年總保費 | N24: =IF(M37,FYPremium+(PayYear-1)*CYPremium,"-") -> 2655727 | O24: =IF(OR(SA="-",E25="不附加"),"-",IF(F25,"-",O22+O23*(PayYear-1))) -> #N/A | P24: 元
M25: 註：本試算表內容數值僅供參考，容有四捨五入之些微誤差，各期實繳保費及實際給付內容仍應以保單面頁數值為準。
K26: ※要被保險人須為同一人，方能執行豁免保費貼現試算頁之試算功能。
B28: 審閱期間確認聲明書標示 「凱基人壽保費融資批註條款」 | E28: 否 | F28: =IF(LoanP="是",IF(OR(SameOwner="是",AND(E33=E11,G33=G11,I33=I11,G32=Sex)),"","※要保人與被保險人須為同一人"),"")
B29: ※投保本商品可申請辦理「保費融資批註條款」，若申請「保費融資批註條款」時，當件保單限制要保人與被保險人須為同一人且必須檢附「辦理保費融資批註條款重要事項告知暨聲明書」。
B30: ※本Excel試算表檔案，需於PC/NB之MS Windows系統及合法授權的MS Office Excel軟體中執行。其他作業系統或非MS Office Excel軟體將可能發生無法預期之錯誤或無法順利運行。
B31: 要保人／實際繳交保費之人資料輸入區
B32: 要保人姓名 | D32: AAA | F32: 性別 | G32: 男性
B33: 要保人生日 | D33: 民國 | E33: 44 | F33: 年 | G33: 1 | H33: 月 | I33: 1 | J33: 日出生 | K33: =IF(DATE(E33+1911,G33,I33)>TODAY(),"請重新輸入生日",IF(ISERROR(DATEVALUE((E33+1911)&"/"&G33&"/"&I33)),"請重新輸入生日","保險年齡："&L39&"歲")) -> 保險年齡：71歲 | N33: =IF(K33="請重新輸入生日","",IF(J46<=10,"※假設試算日為生效日之年齡，再過"&J46&"天保險年齡加1歲。",""))
B34: 實際繳交保費之人姓名 | D34: CCC | F34: 性別 | G34: 男性
B35: 實際繳交保費之人生日 | D35: 民國 | E35: 44 | F35: 年 | G35: 5 | H35: 月 | I35: 16 | J35: 日出生 | K35: =IF(DATE(E35+1911,G35,I35)>TODAY(),"請重新輸入生日",IF(ISERROR(DATEVALUE((E35+1911)&"/"&G35&"/"&I35)),"請重新輸入生日","保險年齡："&L42&"歲")) -> 保險年齡：71歲 | N35: =IF(K35="請重新輸入生日","",IF(J49<=10,"※假設試算日為生效日之年齡，再過"&J49&"天保險年齡加1歲。",""))
B36: 年 | C36: 1 | D36: 1 | E36: ="險種基本資料!"&險種基本資料!B25 -> 險種基本資料!A2:A2 | F36: today | J36: today
B37: 半年 | C37: 2 | D37: 0.52 | E37: 以繳清保險方式增加保險金額 | F37: =YEAR(TODAY()) -> 2026 | G37: =F37-(E11+1911) -> 71 | H37: =IF(OR(AND(G38=0,G39<0),AND(G38<0)),G37-1,G37) -> 71 | J37: =YEAR(TODAY()) -> 2026 | K37: =J37-(IF(SameOwner="是",E11,E33)+1911) -> 71 | L37: =IF(OR(AND(K38=0,K39<0),AND(K38<0)),K37-1,K37) -> 71 | M37: =AND(NOT(OR(OR(E11<>G48,G11<>H48,I11<>I48),OR(H37<0,H39<險種基本資料!D28,H39>險種基本資料!E28),險種基本資料!AO3<MinSA,險種基本資料!AO3>險種基本資料!G28,AND(E18=B45,E19=C44))),M38,M39) -> TRUE
B38: 季 | C38: 4 | D38: 0.262 | F38: =MONTH(TODAY()) -> 2 | G38: =F38-G11 -> 1 | H38: =IF(G39<0,IF(OR(G38<0,AND(G38=0,G39<0)),G38+12-1,G38-1),IF(G38<0,G38+12,G38)) -> 1 | I38: =IF(G11+6>12,G11-6,G11+6) -> 7 | J38: =MONTH(TODAY()) -> 2 | K38: =J38-IF(SameOwner="是",G11,G33) -> 1 | L38: =IF(K39<0,IF(OR(K38<0,AND(K38=0,K39<0)),K38+12-1,K38-1),IF(K38<0,K38+12,K38)) -> 1 | M38: =IF(E12="躉",E13="躉",E13<>"躉") -> TRUE | N38: 判斷繳費年期期繳別是否對應(躉繳應為躉繳，年繳不應躉繳)
A39: =IF(E12="躉","躉繳","期繳") -> 躉繳 | B39: 月 | C39: 12 | D39: 0.088 | F39: =DAY(TODAY()) -> 25 | G39: =F39-I11 -> 2 | H39: =H37+ROUND(H38/12,0)-IF(AND(ABS(G38)=6,G39=0),1,0) -> 71 | J39: =DAY(TODAY()) -> 25 | K39: =J39-IF(SameOwner="是",I11,I33) -> 2 | L39: =L37+ROUND(L38/12,0)-IF(AND(ABS(K38)=6,K39=0),1,0) -> 71 | M39: =IF(AND(PayYear=1,LoanP="是"),IF(SameOwner="是","",IF(AND(Sex=G32,E11=E33,G11=G33,I11=I33),TRUE,FALSE)),TRUE) -> TRUE
A40: 2 | B40: 躉 | C40: 1 | D40: 1 | J40: =YEAR(TODAY()) -> 2026 | K40: =J40-(IF(SameOwner="是",E11,E35)+1911) -> 71 | L40: =IF(OR(AND(K41=0,K42<0),AND(K41<0)),K40-1,K40) -> 71
B41: 男性 | C41: 1 | D41: 先生 | F41: =F37 -> 2026 | G41: =IF(G11+6>12,G11-6,G11+6) -> 7 | H41: =MIN(DAY(DATE(YEAR(TODAY()),IF(G11+6>12,G11-6,G11+6)+1,1)-1),I11) -> 23 | J41: =MONTH(TODAY()) -> 2 | K41: =J41-IF(SameOwner="是",G11,G35) -> 1 | L41: =IF(K42<0,IF(OR(K41<0,AND(K41=0,K42<0)),K41+12-1,K41-1),IF(K41<0,K41+12,K41)) -> 1
B42: 女性 | C42: 2 | D42: 女士 | F42: =IF(DATE(F41,G41,H41)<TODAY(),F41+1,F41) -> 2026 | G42: =G41 -> 7 | H42: =MIN(DAY(DATE(F42,G42+1,1)-1),I11) -> 23 | J42: =DAY(TODAY()) -> 25 | K42: =J42-IF(SameOwner="是",I11,I35) -> 2 | L42: =L40+ROUND(L41/12,0)-IF(AND(ABS(K41)=6,K42=0),1,0) -> 71
...

Sheet 險種基本資料
B1: 年期清單 | C1: 預定利率 | D1: 危額係數 | E1: 高保費費率折減 | F1: 投保年齡下限 | G1: 投保年齡上限 | H1: 保額下限 | I1: 保額上限 | J1: offset | L1: 解約金表 | M1: 年期 | X1: 2年期 | AI1: 銀保 | AJ1: 面額計算額度則危險係數放1
A2: 躉 | B2: 1 | C2: 1.85 | D2: =IF(Age>=71,0.2,IF(Age>=61,0.2,IF(Age>=51,0.3,IF(Age>=41,0.4,IF(Age>=31,0.4,IF(Age>=16,0.45,0.45)))))) -> 0.2 | E2: =IF(Premium>=1500000,7%,IF(Premium>=1200000,5.5%,IF(Premium>=800000,4%,IF(Premium>=500000,3%,IF(Premium>=200000,2%,IF(Premium>=100000,1%,0%)))))) -> 0.07 | F2: 18 | G2: 75 | H2: 3000 | I2: 10000000 | J2: 0 | L2: 年度 | M2: =OFFSET($B$2,0,0) -> 1 | N2: =OFFSET($B$2,1,0) -> 0 | O2: =OFFSET($B$2,2,0) -> 0 | P2: =OFFSET($B$2,3,0) -> 0 | Q2: =OFFSET($B$2,4,0) -> 0 | R2: =OFFSET($B$2,5,0) -> 0 | S2: =OFFSET($B$2,6,0) -> 0 | T2: =OFFSET($B$2,7,0) -> 0 | U2: =OFFSET($B$2,8,0) -> 0 | V2: =OFFSET($B$2,9,0) -> 0 | X2: 性別 | Z2: 男性 | AC2: 女性 | AG2: 年期 | AH2: 年齡下限 | AI2: 危險係數 | AK2: 年齡下限 | AL2: 主約免體檢額度 | AM2: 有附約 | AO2: =MAX(AR:AR) -> 5160101 | AP2: =ROUNDDOWN(資料輸入區!E15/(1-G45)/UNIT*UVUNIT/GP,0) -> 5160101 | AQ2: =ROUND(ROUND(ROUND(ROUNDDOWN(ROUND(AP2*UNIT/UVUNIT*GP,3),2),3),0)*(1-$G$45),0) -> 3701867 | AR2: =IF(AQ2>資料輸入區!$E$15,0,AP2) -> 5160101
J3: 1 | L3: 1 | M3: 0.08 | X3: 年齡 | Z3: 18 | AA3: 35 | AB3: 65 | AC3: 18 | AD3: 35 | AE3: 65 | AG3: 6 | AH3: 0 | AI3: 1 | AK3: 0 | AL3: 500 | AM3: 1000 | AO3: =IF(資料輸入區!E14="保費",險種基本資料!AO2,資料輸入區!E15) -> 3701867 | AP3: =AP2+1 -> 5160102 | AQ3: =ROUND(ROUND(ROUND(ROUNDDOWN(ROUND(AP3*UNIT/UVUNIT*GP,3),2),3),0)*(1-$G$45),0) -> 3701868 | AR3: =IF(AQ3>資料輸入區!$E$15,0,AP3) -> 0
J4: 2 | L4: 2 | M4: 0.08 | X4: 保單 年度 | Y4: 1 | Z4: 0.79 | AA4: 0.8 | AB4: 0.8 | AC4: 0.79 | AD4: 0.79 | AE4: 0.8 | AG4: 6 | AH4: 16 | AI4: 1 | AK4: 16 | AL4: 500 | AM4: 900 | AO4: =VLOOKUP(資料輸入區!E13,資料輸入區!B36:C40,2,0)*資料輸入區!N14 -> 2855620 | AP4: =AP3+1 -> 5160103 | AQ4: =ROUND(ROUND(ROUND(ROUNDDOWN(ROUND(AP4*UNIT/UVUNIT*GP,3),2),3),0)*(1-$G$45),0) -> 3701868 | AR4: =IF(AQ4>資料輸入區!$E$15,0,AP4) -> 0
J5: 3 | L5: 3 | M5: 0.01 | Y5: 2 | Z5: 0.79 | AA5: 0.8 | AB5: 0.8 | AC5: 0.79 | AD5: 0.79 | AE5: 0.79 | AG5: 6 | AH5: 31 | AI5: 1 | AK5: 46 | AL5: 500 | AM5: 800 | AP5: =AP4+1 -> 5160104 | AQ5: =ROUND(ROUND(ROUND(ROUNDDOWN(ROUND(AP5*UNIT/UVUNIT*GP,3),2),3),0)*(1-$G$45),0) -> 3701869 | AR5: =IF(AQ5>資料輸入區!$E$15,0,AP5) -> 0
J6: 4 | L6: 4 | M6: 0.01 | Y6: 3 | Z6: 0.85 | AA6: 0.86 | AB6: 0.85 | AC6: 0.85 | AD6: 0.85 | AE6: 0.85 | AG6: 6 | AH6: 41 | AI6: 1 | AK6: 51 | AL6: 500 | AM6: 550 | AP6: =AP5+1 -> 5160105 | AQ6: =ROUND(ROUND(ROUND(ROUNDDOWN(ROUND(AP6*UNIT/UVUNIT*GP,3),2),3),0)*(1-$G$45),0) -> 3701870 | AR6: =IF(AQ6>資料輸入區!$E$15,0,AP6) -> 0
J7: 5 | L7: 5 | M7: 0.01 | Y7: 4 | Z7: 0.85 | AA7: 0.86 | AB7: 0.85 | AC7: 0.85 | AD7: 0.85 | AE7: 0.85 | AG7: 6 | AH7: 51 | AI7: 1 | AK7: 56 | AL7: 500 | AM7: 250 | AP7: =AP6+1 -> 5160106 | AQ7: =ROUND(ROUND(ROUND(ROUNDDOWN(ROUND(AP7*UNIT/UVUNIT*GP,3),2),3),0)*(1-$G$45),0) -> 3701871 | AR7: =IF(AQ7>資料輸入區!$E$15,0,AP7) -> 0
J8: 6 | L8: 6 | M8: 0.01 | Y8: 5 | Z8: 0.85 | AA8: 0.85 | AB8: 0.84 | AC8: 0.85 | AD8: 0.85 | AE8: 0.85 | AG8: 6 | AH8: 61 | AI8: 1 | AK8: 61 | AL8: 500 | AM8: 100 | AP8: =AP7+1 -> 5160107 | AQ8: =ROUND(ROUND(ROUND(ROUNDDOWN(ROUND(AP8*UNIT/UVUNIT*GP,3),2),3),0)*(1-$G$45),0) -> 3701872 | AR8: =IF(AQ8>資料輸入區!$E$15,0,AP8) -> 0
J9: 7 | L9: 7 | M9: 0 | Y9: 10 | Z9: 0.85 | AA9: 0.84 | AB9: 0.8 | AC9: 0.85 | AD9: 0.85 | AE9: 0.82 | AG9: 6 | AH9: 71 | AI9: 1 | AK9: 66 | AL9: 500 | AM9: 0 | AP9: =AP8+1 -> 5160108 | AQ9: =ROUND(ROUND(ROUND(ROUNDDOWN(ROUND(AP9*UNIT/UVUNIT*GP,3),2),3),0)*(1-$G$45),0) -> 3701872 | AR9: =IF(AQ9>資料輸入區!$E$15,0,AP9) -> 0
J10: 8 | L10: 8 | M10: 0 | Y10: 15 | Z10: 0.83 | AA10: 0.81 | AB10: 0.73 | AC10: 0.84 | AD10: 0.83 | AE10: 0.77 | AK10: 71 | AL10: 50 | AP10: =AP9+1 -> 5160109 | AQ10: =ROUND(ROUND(ROUND(ROUNDDOWN(ROUND(AP10*UNIT/UVUNIT*GP,3),2),3),0)*(1-$G$45),0) -> 3701872 | AR10: =IF(AQ10>資料輸入區!$E$15,0,AP10) -> 0
J11: 9 | L11: 9 | M11: 0 | Y11: 20 | Z11: 0.82 | AA11: 0.78 | AB11: 0.67 | AC11: 0.83 | AD11: 0.82 | AE11: 0.71 | AP11: =AP10+1 -> 5160110 | AQ11: =ROUND(ROUND(ROUND(ROUNDDOWN(ROUND(AP11*UNIT/UVUNIT*GP,3),2),3),0)*(1-$G$45),0) -> 3701873 | AR11: =IF(AQ11>資料輸入區!$E$15,0,AP11) -> 0
L12: 10 | M12: 0 | AP12: =AP11+1 -> 5160111 | AQ12: =ROUND(ROUND(ROUND(ROUNDDOWN(ROUND(AP12*UNIT/UVUNIT*GP,3),2),3),0)*(1-$G$45),0) -> 3701874 | AR12: =IF(AQ12>資料輸入區!$E$15,0,AP12) -> 0
A13: 保額單位 | B13: 1 | F13: =PMST -> 抵繳應繳保險費 | G13: 抵繳應繳保險費 | L13: 11 | M13: 0 | X13: 6年期 | AI13: 經代 | AJ13: 面額計算額度則危險係數放1 | AP13: =AP12+1 -> 5160112 | AQ13: =ROUND(ROUND(ROUND(ROUNDDOWN(ROUND(AP13*UNIT/UVUNIT*GP,3),2),3),0)*(1-$G$45),0) -> 3701874 | AR13: =IF(AQ13>資料輸入區!$E$15,0,AP13) -> 0
A14: 精算單位 | B14: 10000 | F14: =PUAD -> 以繳清保險方式增加保險金額 | G14: 現金給付 | L14: 12 | M14: 0 | X14: 性別 | Z14: 男性 | AC14: 女性 | AG14: 年期 | AH14: 年齡下限 | AI14: 危險係數 | AK14: 年齡下限 | AL14: 主約免體檢額度 | AM14: 有附約 | AP14: =AP13+1 -> 5160113 | AQ14: =ROUND(ROUND(ROUND(ROUNDDOWN(ROUND(AP14*UNIT/UVUNIT*GP,3),2),3),0)*(1-$G$45),0) -> 3701875 | AR14: =IF(AQ14>資料輸入區!$E$15,0,AP14) -> 0
A15: 四捨五入 | B15: 2 | G15: 儲存生息 | L15: 13 | M15: 0 | X15: 年齡 | AG15: 6 | AH15: 0 | AI15: 1 | AK15: 0 | AL15: 115 | AM15: 600 | AP15: =AP14+1 -> 5160114 | AQ15: =ROUND(ROUND(ROUND(ROUNDDOWN(ROUND(AP15*UNIT/UVUNIT*GP,3),2),3),0)*(1-$G$45),0) -> 3701876 | AR15: =IF(AQ15>資料輸入區!$E$15,0,AP15) -> 0
A16: 增額繳清年度 | B16: 5 | G16: 以繳清保險方式增加保險金額 | L16: 14 | M16: 0 | X16: 保單 年度 | Y16: 1 | AG16: 6 | AH16: 16 | AI16: 1 | AK16: 41 | AL16: 115 | AM16: 500 | AP16: =AP15+1 -> 5160115 | AQ16: =ROUND(ROUND(ROUND(ROUNDDOWN(ROUND(AP16*UNIT/UVUNIT*GP,3),2),3),0)*(1-$G$45),0) -> 3701877 | AR16: =IF(AQ16>資料輸入區!$E$15,0,AP16) -> 0
A17: 生存險 | B17: FALSE | L17: 15 | M17: 0 | Y17: 2 | AG17: 6 | AH17: 31 | AI17: 1 | AK17: 46 | AL17: 115 | AM17: 500 | AP17: =AP16+1 -> 5160116 | AQ17: =ROUND(ROUND(ROUND(ROUNDDOWN(ROUND(AP17*UNIT/UVUNIT*GP,3),2),3),0)*(1-$G$45),0) -> 3701877 | AR17: =IF(AQ17>資料輸入區!$E$15,0,AP17) -> 0
A18: 三者取其大保費倍數 | B18: 1 | E18: 15歲以下危額上限 | L18: 16 | M18: 0 | Y18: 3 | AG18: 6 | AH18: 41 | AI18: 1 | AK18: 51 | AL18: 90 | AM18: 200 | AP18: =AP17+1 -> 5160117 | AQ18: =ROUND(ROUND(ROUND(ROUNDDOWN(ROUND(AP18*UNIT/UVUNIT*GP,3),2),3),0)*(1-$G$45),0) -> 3701878 | AR18: =IF(AQ18>資料輸入區!$E$15,0,AP18) -> 0
A19: 幣別 | B19: USD | C19: 分期定期給付門檻BY匯率 | F19: 10000000 | L19: 17 | M19: 0 | Y19: 4 | AG19: 6 | AH19: 51 | AI19: 1 | AK19: 56 | AL19: 90 | AM19: 100 | AP19: =AP18+1 -> 5160118 | AQ19: =ROUND(ROUND(ROUND(ROUNDDOWN(ROUND(AP19*UNIT/UVUNIT*GP,3),2),3),0)*(1-$G$45),0) -> 3701879 | AR19: =IF(AQ19>資料輸入區!$E$15,0,AP19) -> 0
A20: 核保匯率 | B20: =VLOOKUP(B19,A30:B33,2,FALSE) -> 31.5 | C20: =VLOOKUP(B19,A30:D33,3,FALSE) -> 1000 | D20: =VLOOKUP(B19,A30:D33,4,FALSE) -> 5000 | L20: 18 | M20: 0 | Y20: 5 | AG20: 6 | AH20: 61 | AI20: 1 | AK20: 61 | AL20: 75 | AM20: 0 | AP20: =AP19+1 -> 5160119 | AQ20: =ROUND(ROUND(ROUND(ROUNDDOWN(ROUND(AP20*UNIT/UVUNIT*GP,3),2),3),0)*(1-$G$45),0) -> 3701880 | AR20: =IF(AQ20>資料輸入區!$E$15,0,AP20) -> 0
A21: 保障至 | B21: 109 | C21: 歲 | I21: 適用通路 | J21: 危額係數體檢額度位置 | L21: 19 | M21: 0 | Y21: 10 | AG21: 6 | AH21: 66 | AI21: 1 | AK21: 66 | AL21: 15 | AM21: 0 | AP21: =AP20+1 -> 5160120 | AQ21: =ROUND(ROUND(ROUND(ROUNDDOWN(ROUND(AP21*UNIT/UVUNIT*GP,3),2),3),0)*(1-$G$45),0) -> 3701881 | AR21: =IF(AQ21>資料輸入區!$E$15,0,AP21) -> 0
A22: 門檻 | B22: Corridor210 | C22: =MATCH(B22,A36:E36,0) -> 4 | G22: 體檢匯率 | H22: 1 | I22: 銀保 | J22: ="AH"&MATCH(I22,AI:AI,0)&":AI"&(MATCH(I22,AI:AI,0)+11) -> AH1:AI12 | K22: ="AK"&MATCH(I22,AI:AI,0)&":AM"&(MATCH(I22,AI:AI,0)+11) -> AK1:AM12 | L22: 20 | M22: 0 | Y22: 15 | AK22: 71 | AL22: 10 | AP22: =AP21+1 -> 5160121 | AQ22: =ROUND(ROUND(ROUND(ROUNDDOWN(ROUND(AP22*UNIT/UVUNIT*GP,3),2),3),0)*(1-$G$45),0) -> 3701881 | AR22: =IF(AQ22>資料輸入區!$E$15,0,AP22) -> 0
B23: 年期數 | C23: PAY_YEAR | D23: SEX | E23: AGE | F23: 費率 | G23: 危險保額 | H23: 體檢危額 | I23: 免體檢額度 | J23: 體檢與否 | L23: 21 | M23: 0 | Y23: 20 | AP23: =AP22+1 -> 5160122 | AQ23: =ROUND(ROUND(ROUND(ROUNDDOWN(ROUND(AP23*UNIT/UVUNIT*GP,3),2),3),0)*(1-$G$45),0) -> 3701882 | AR23: =IF(AQ23>資料輸入區!$E$15,0,AP23) -> 0
B24: =COUNT(B2:B11) -> 1 | C24: =TEXT(PayYear,"00") -> 01 | D24: =TEXT(VLOOKUP(Sex,資料輸入區!B41:C42,2,FALSE),"0") -> 1 | E24: =TEXT(Age,"00") -> 71 | F24: =DGET(Premium!A:D,"GP",險種基本資料!$C$23:$E$24) -> 7714 | G24: =險種基本資料!AO3*VLOOKUP(PayYear,B2:D9,3,FALSE)*B20 -> 23321762 | H24: =VLOOKUP(E24*1,INDIRECT(J22),2)*1*SA -> 3701867 | I24: =VLOOKUP(E24*1,INDIRECT(K22),2)*10000 -> 500000 | J24: =IF(SA="-",0,IF(H24>I24,1,0)) -> 1 | K24: 主約 | L24: 22 | M24: 0 | AP24: =AP23+1 -> 5160123 | AQ24: =ROUND(ROUND(ROUND(ROUNDDOWN(ROUND(AP24*UNIT/UVUNIT*GP,3),2),3),0)*(1-$G$45),0) -> 3701883 | AR24: =IF(AQ24>資料輸入區!$E$15,0,AP24) -> 0
B25: ="A2:A"&B24+1 -> A2:A2 | I25: =VLOOKUP(E24*1,INDIRECT(K22),3)*10000 -> 0 | J25: 0 | K25: 附約 | L25: 23 | M25: 0 | X25: 8年期 | AI25: 業務 | AJ25: 面額計算額度則危險係數放1 | AP25: =AP24+1 -> 5160124 | AQ25: =ROUND(ROUND(ROUND(ROUNDDOWN(ROUND(AP25*UNIT/UVUNIT*GP,3),2),3),0)*(1-$G$45),0) -> 3701884 | AR25: =IF(AQ25>資料輸入區!$E$15,0,AP25) -> 0
J26: =SUM(J24:J25) -> 1 | K26: 主附約 | L26: 24 | M26: 0 | X26: 性別 | Z26: 男性 | AC26: 女性 | AG26: 年期 | AH26: 年齡下限 | AI26: 危險係數 | AK26: 年齡下限 | AL26: 主約免體檢額度 | AM26: 有附約 | AP26: =AP25+1 -> 5160125 | AQ26: =ROUND(ROUND(ROUND(ROUNDDOWN(ROUND(AP26*UNIT/UVUNIT*GP,3),2),3),0)*(1-$G$45),0) -> 3701884 | AR26: =IF(AQ26>資料輸入區!$E$15,0,AP26) -> 0
A27: 預定利率 | B27: 危額係數 | C27: 高保額費率折減 | D27: 投保年齡下限 | E27: 投保年齡上限 | F27: 保額下限 | G27: 保額上限 | H27: offset | I27: 是否有PVA | L27: 25 | M27: 0 | X27: 年齡 | AG27: 6 | AH27: 0 | AI27: 1 | AK27: 0 | AL27: 115 | AM27: 600 | AP27: =AP26+1 -> 5160126 | AQ27: =ROUND(ROUND(ROUND(ROUNDDOWN(ROUND(AP27*UNIT/UVUNIT*GP,3),2),3),0)*(1-$G$45),0) -> 3701885 | AR27: =IF(AQ27>資料輸入區!$E$15,0,AP27) -> 0
A28: 1.75 | B28: =VLOOKUP(PayYear,B2:J11,3,FALSE) -> 0.2 | C28: =VLOOKUP(PayYear,B2:J11,4,FALSE) -> 0.07 | D28: =VLOOKUP(PayYear,B2:J11,5,FALSE) -> 18 | E28: =VLOOKUP(PayYear,B2:J11,6,FALSE) -> 75 | F28: =VLOOKUP(PayYear,B2:J11,7,FALSE) -> 3000 | G28: =VLOOKUP(PayYear,B2:J11,8,FALSE) -> 10000000 | H28: =VLOOKUP(PayYear,B2:J11,9,FALSE) -> 0 | I28: N | L28: 26 | M28: 0 | N28: 0 | O28: 0 | X28: 保單 年度 | Y28: 1 | AG28: 6 | AH28: 16 | AI28: 1 | AK28: 41 | AL28: 115 | AM28: 500 | AP28: =AP27+1 -> 5160127 | AQ28: =ROUND(ROUND(ROUND(ROUNDDOWN(ROUND(AP28*UNIT/UVUNIT*GP,3),2),3),0)*(1-$G$45),0) -> 3701885 | AR28: =IF(AQ28>資料輸入區!$E$15,0,AP28) -> 0
L29: 27 | M29: 0 | N29: 0 | O29: 0 | Y29: 2 | AG29: 6 | AH29: 31 | AI29: 1 | AK29: 46 | AL29: 115 | AM29: 500 | AP29: =AP28+1 -> 5160128 | AQ29: =ROUND(ROUND(ROUND(ROUNDDOWN(ROUND(AP29*UNIT/UVUNIT*GP,3),2),3),0)*(1-$G$45),0) -> 3701886 | AR29: =IF(AQ29>資料輸入區!$E$15,0,AP29) -> 0
A30: NTD | B30: 1 | C30: 20000 | D30: 100000 | L30: 28 | M30: 0 | N30: 0 | O30: 0 | Y30: 3 | AG30: 6 | AH30: 41 | AI30: 1 | AK30: 51 | AL30: 90 | AM30: 200 | AP30: =AP29+1 -> 5160129 | AQ30: =ROUND(ROUND(ROUND(ROUNDDOWN(ROUND(AP30*UNIT/UVUNIT*GP,3),2),3),0)*(1-$G$45),0) -> 3701887 | AR30: =IF(AQ30>資料輸入區!$E$15,0,AP30) -> 0
A31: USD | B31: 31.5 | C31: 1000 | D31: 5000 | L31: 29 | M31: 0 | N31: 0 | O31: 0 | Y31: 4 | AG31: 6 | AH31: 51 | AI31: 1 | AK31: 56 | AL31: 90 | AM31: 100 | AP31: =AP30+1 -> 5160130 | AQ31: =ROUND(ROUND(ROUND(ROUNDDOWN(ROUND(AP31*UNIT/UVUNIT*GP,3),2),3),0)*(1-$G$45),0) -> 3701887 | AR31: =IF(AQ31>資料輸入區!$E$15,0,AP31) -> 0
A32: CNY | B32: 4.5 | L32: 30 | M32: 0 | N32: 0 | O32: 0 | Y32: 5 | AG32: 6 | AH32: 61 | AI32: 1 | AK32: 61 | AL32: 75 | AM32: 0 | AP32: =AP31+1 -> 5160131 | AQ32: =ROUND(ROUND(ROUND(ROUNDDOWN(ROUND(AP32*UNIT/UVUNIT*GP,3),2),3),0)*(1-$G$45),0) -> 3701888 | AR32: =IF(AQ32>資料輸入區!$E$15,0,AP32) -> 0
A33: AUD | B33: 21 | L33: 31 | M33: 0 | N33: 0 | O33: 0 | Y33: 10 | AG33: 6 | AH33: 66 | AI33: 1 | AK33: 66 | AL33: 15 | AM33: 0 | AP33: =AP32+1 -> 5160132 | AQ33: =ROUND(ROUND(ROUND(ROUNDDOWN(ROUND(AP33*UNIT/UVUNIT*GP,3),2),3),0)*(1-$G$45),0) -> 3701889 | AR33: =IF(AQ33>資料輸入區!$E$15,0,AP33) -> 0
L34: 32 | M34: 0 | N34: 0 | O34: 0 | Y34: 15 | AK34: 71 | AL34: 10 | AP34: =AP33+1 -> 5160133 | AQ34: =ROUND(ROUND(ROUND(ROUNDDOWN(ROUND(AP34*UNIT/UVUNIT*GP,3),2),3),0)*(1-$G$45),0) -> 3701890 | AR34: =IF(AQ34>資料輸入區!$E$15,0,AP34) -> 0
H35: 躉繳保費達高保額折扣金額 | L35: 33 | M35: 0 | N35: 0 | O35: 0 | Y35: 20 | AP35: =AP34+1 -> 5160134 | AQ35: =ROUND(ROUND(ROUND(ROUNDDOWN(ROUND(AP35*UNIT/UVUNIT*GP,3),2),3),0)*(1-$G$45),0) -> 3701890 | AR35: =IF(AQ35>資料輸入區!$E$15,0,AP35) -> 0
A36: 年齡 | B36: Corridor100 | C36: Corridor190 | D36: Corridor210 | E36: Corridor250 | G36: 保費折扣 | H36: 原始保費 | I36: 折扣後保費 | L36: 34 | M36: 0 | N36: 0 | O36: 0 | AP36: =AP35+1 -> 5160135 | AQ36: =ROUND(ROUND(ROUND(ROUNDDOWN(ROUND(AP36*UNIT/UVUNIT*GP,3),2),3),0)*(1-$G$45),0) -> 3701891 | AR36: =IF(AQ36>資料輸入區!$E$15,0,AP36) -> 0
A37: 0 | B37: 1 | C37: 1.9 | D37: 2.1 | E37: 2.5 | G37: 0.07 | H37: 1500000 | I37: =H37*(1-G37) -> 1395000 | L37: 35 | M37: 0 | N37: 0 | O37: 0 | AP37: =AP36+1 -> 5160136 | AQ37: =ROUND(ROUND(ROUND(ROUNDDOWN(ROUND(AP37*UNIT/UVUNIT*GP,3),2),3),0)*(1-$G$45),0) -> 3701892 | AR37: =IF(AQ37>資料輸入區!$E$15,0,AP37) -> 0
A38: 1 | B38: 1 | C38: 1.9 | D38: 2.1 | E38: 2.5 | G38: 0.055 | H38: 1200000 | I38: =H38*(1-G38) -> 1134000 | L38: 36 | M38: 0 | N38: 0 | O38: 0 | X38: 性別 | AP38: =AP37+1 -> 5160137 | AQ38: =ROUND(ROUND(ROUND(ROUNDDOWN(ROUND(AP38*UNIT/UVUNIT*GP,3),2),3),0)*(1-$G$45),0) -> 3701893 | AR38: =IF(AQ38>資料輸入區!$E$15,0,AP38) -> 0
A39: 2 | B39: 1 | C39: 1.9 | D39: 2.1 | E39: 2.5 | G39: 0.04 | H39: 800000 | I39: =H39*(1-G39) -> 768000 | L39: 37 | M39: 0 | N39: 0 | O39: 0 | X39: 年齡 | Z39: 0 | AA39: 35 | AB39: 65 | AC39: 0 | AD39: 35 | AE39: 65 | AP39: =AP38+1 -> 5160138 | AQ39: =ROUND(ROUND(ROUND(ROUNDDOWN(ROUND(AP39*UNIT/UVUNIT*GP,3),2),3),0)*(1-$G$45),0) -> 3701893 | AR39: =IF(AQ39>資料輸入區!$E$15,0,AP39) -> 0
A40: 3 | B40: 1 | C40: 1.9 | D40: 2.1 | E40: 2.5 | G40: 0.03 | H40: 500000 | I40: =H40*(1-G40) -> 485000 | L40: 38 | M40: 0 | N40: 0 | O40: 0 | X40: 保單 年度 | Y40: 1 | AP40: =AP39+1 -> 5160139 | AQ40: =ROUND(ROUND(ROUND(ROUNDDOWN(ROUND(AP40*UNIT/UVUNIT*GP,3),2),3),0)*(1-$G$45),0) -> 3701894 | AR40: =IF(AQ40>資料輸入區!$E$15,0,AP40) -> 0
...

Sheet 明細版-試算頁
B2: =資料輸入區!B2 -> 凱基人壽美利成臻美元利率變動型終身壽險－定期給付型
Q3: 單位：美元
D4: 性 別： | F4: =Sex -> 男性 | G4: 繳費期間： | J4: =IF(PayYear=1,"躉繳",PayYear&"年期") -> 躉繳 | L4: 經費率折減後躉繳保費： | O4: =firstpay -> 2655727 | P4: =IF(資料輸入區!E13="月","※月繳件首期須繳交2個月保費。","")
C5: 保險年齡： | F5: =Age&"歲" -> 71歲 | G5: 繳費方式： | J5: =資料輸入區!E13&"繳" -> 躉繳 | L5: 續期繳交保險費(經費率折減後)： | O5: =資料輸入區!N21 -> -7583744280120
B6: 本月宣告利率(預估值)： | F6: =DecareRate -> 4.35 | G6: 投保金額： | J6: =SA -> 3701867 | L6: =IF(PayYear=1,"高保費費率折減：","首期"&IF(資料輸入區!N15>0,"高保費與","")&資料輸入區!E16&"費率折減：") -> 高保費費率折減： | O6: =資料輸入區!N18 -> 0.07
C7: 預定利率： | F7: =PDRate -> 1.75 | G7: 原始躉繳保費： | J7: =資料輸入區!N14 -> 2855620 | L7: ="續期"&IF(資料輸入區!N15>0,"高保費與","")&資料輸入區!E17&"費率折減：" -> 續期高保費與金融機構轉帳費率折減： | O7: =資料輸入區!N19 -> 2,655,727
D9: 各保單年度末 增值回饋分享金 選擇給付方式： | G9: =IF(MAX(宣告利率!AD:AD)>0,"第1保單年度"&IF(MAX(宣告利率!AD:AD)=1,"","~第"&MAX(宣告利率!AD:AD)&"保單年度"),"") | J9: =IF(G9="","",PMST) | M9: =IF(Age<16,"※ 被保險人保險年齡到達16歲之保單週年日時，其增值回饋分享金請參照保單條款。","")
G10: =IF(OR(MAX(宣告利率!AE:AE)>0,AND(MAX(宣告利率!AE:AE)>PUAYear,ZDIVOPT02=DVAC)),"第"&MAX(宣告利率!AD:AD)+1&IF(OR(MAX(宣告利率!AE:AE)<PUAYear,ZDIVOPT02<>DVAC),IF(MAX(宣告利率!AD:AD)+1=MAX(宣告利率!AE:AE),"保單年度","保單年度~第"&MAX(宣告利率!AE:AE)&"保單年度"),"保單年度起"),"") | J10: =IF(G10="","",DVAC)
G11: =IF(OR(AND(PayYear=PUAYear,Age>15),ZDIVOPT02=PUAD,MAX(宣告利率!AD:AE)<PUAYear),"第"&MAX(宣告利率!AD:AE)+1&IF(ZDIVOPT02=PUAD,"保單年度起",IF(MAX(宣告利率!AD:AE)+1=PUAYear,"保單年度","保單年度~第"&PUAYear&"保單年度")),"") -> 第1保單年度起 | J11: =IF(G11="","",PUAD) -> 以繳清保險方式增加保險金額
G12: =IF(ZDIVOPT02='明細版-試算頁'!J11,"",IF(AND('明細版-試算頁'!J11="",ZDIVOPT02='明細版-試算頁'!J10),"","第"&MAX(MAX(宣告利率!AD:AD)+1,MAX(宣告利率!AE:AE)+1,IF(ZDIVOPT02=PMST,PayYear,PUAYear+1))&"保單年度起")) | J12: =IF(G12="","",IF(ZDIVOPT02=PMST,PUAD,ZDIVOPT02))
B13: =IF(資料輸入區!H37<15,"※ 未滿15足歲之被保險人所投保之喪葬費用保險金額，不得超過遺產及贈與稅法第十七條有關遺產稅喪葬費扣除額之半數。","")
C14: 契約生效日首日預估保單價值準備金： | G14: =ROUND((宣告利率!K3+宣告利率!M3)/(1+PDRate/100)^(364/365)/VLOOKUP(資料輸入區!E13,資料輸入區!B36:C40,2,FALSE)*IF(VLOOKUP(資料輸入區!E13,資料輸入區!B36:C40,2,FALSE)=12,2,1),0) -> 2462814 | J14: 契約生效首日預估現金價值(解約金)： | M14: =ROUND((宣告利率!K3+宣告利率!L3)/(1+PDRate/100)^(364/365)/VLOOKUP(資料輸入區!E13,資料輸入區!B36:C40,2,FALSE)*IF(VLOOKUP(資料輸入區!E13,資料輸入區!B36:C40,2,FALSE)=12,2,1),0) -> 2265614
Q16: 單位：美元
B17: 保單 年度 (末) | C17: 保險 年齡 | D17: =IF(OR(Age<16,ZDIVOPT01=PMST),"累積所繳保險費(扣除抵繳保費) (A) (註2)","累積所繳保險費 (A)") -> 累積所繳保險費 (A) | E17: 基本保險金額對應之保單價值準備金 【含祝壽保險金】 | F17: 基本保險金額 對應之現金價值 【含祝壽保險金】 (B) | G17: 基本保險金額 對應之壽險保障 (身故保險金) | J17: ="假設投保後未來各保單年度宣告利率為"&TEXT(DecareRate,"0.00")&"% (下表為預估假設值)" -> 假設投保後未來各保單年度宣告利率為4.35% (下表為預估假設值) | R17: ="年度末終止契約時合計可領取之金額(含增值回饋分享金) (F)"&IF(ZDIVOPT02=CSWD,"+(D)","")&IF(ZDIVOPT02=DVAC,"+(E)","") -> 年度末終止契約時合計可領取之金額(含增值回饋分享金) (F) | S17: ="次年度期初終止契約時合計可領取之金額(含增值回饋分享金) (H)=(G)"&IF(ZDIVOPT02=CSWD,"+(D)","")&IF(ZDIVOPT02=DVAC,"+(E)","") -> 次年度期初終止契約時合計可領取之金額(含增值回饋分享金) (H)=(G) | T17: 累積 應繳保費 | U17: 期末保單價值準備金(含基本保險金額、累計增加保險金額) 【含祝壽保險金】 | V17: (E)+(F) | W17: ((E)+(F))/(A) | X17: (G)+(E) | Y17: ((G)+(E))/(A) | Z17: (I)/(A)
H18: 增值回饋分享金 | I18: 選擇以繳清保險方式增加保險金額 | M18: ="選擇"&IF(ZDIVOPT02=DVAC,DVAC,CSWD) -> 選擇現金給付 | O18: 下表數值含「基本保險金額、累計增加保險金額」
I19: 增額繳清保險金額 | J19: 累計增加 保險金額 | K19: 累計增加保險金額對應之年度末保單價值準備金 【含祝壽保險金】 | L19: 累計增加保險金額對應之現金價值 【含祝壽保險金】(C) | M19: 增值回饋 分享金 (D) | N19: =IF(ZDIVOPT02=DVAC,DVAC,"累計之增值回饋分享金")&" (E)" -> 累計之增值回饋分享金 (E) | O19: 壽險保障 (身故保險金) (I) | P19: 年度末現金價值 【含祝壽保險金】 (F)=(B)+(C) | Q19: 次年度期初 現金價值 (G)
B20: 1 | C20: =Age -> 71 | D20: =IF(B20="","",OFFSET(宣告利率!$I$2,B20,0)) -> 2655727 | E20: =IF(B20="","",OFFSET(宣告利率!$M$2,B20,0)+OFFSET(宣告利率!$K$2,B20,0)) -> 2505794 | F20: =IF(B20="","",OFFSET(宣告利率!$L$2,B20,0)+OFFSET(宣告利率!$K$2,B20,0)) -> 2305153 | G20: =IF(B20="","",OFFSET(宣告利率!$J$2,B20,0)) -> 2855620 | H20: =IF(B20="","",OFFSET(宣告利率!$G$2,B20,0)) -> 65151 | I20: =IF(B20="","",IF(C20<16,0,IF(C20=16,OFFSET(宣告利率!$O$2,B20-1,0),0)+OFFSET(宣告利率!$O$2,B20,0))) -> 96249 | J20: =IF(B20="","",IF(C20<16,0,OFFSET(宣告利率!$P$2,B20,0))) -> 96249 | K20: =IF(B20="","",IF(C20<16,OFFSET(宣告利率!$N$2,B20,0)+OFFSET(宣告利率!$U$2,B20,0),OFFSET(宣告利率!$Q$2,B20,0)+OFFSET(宣告利率!$U$2,B20,0))) -> 65151 | L20: =IF(B20="","",IF(C20<16,OFFSET(宣告利率!$N$2,B20,0),OFFSET(宣告利率!$Q$2,B20,0)+OFFSET(宣告利率!$U$2,B20,0))) -> 65151 | M20: =IF(B20="","",IF(OR(ZDIVOPT02=CSWD,ZDIVOPT02=DVAC),OFFSET(宣告利率!$R$2,B20,0),0)) -> 0 | N20: =IF(B20="","",IF(ZDIVOPT02=CSWD,OFFSET(宣告利率!$S$2,B20,0),IF(ZDIVOPT02=DVAC,OFFSET(宣告利率!$T$2,B20,0),0))) -> 0 | O20: =IF(B20="","",IF(C20<0,0,OFFSET(宣告利率!$J$2,B20,0)+MAX(OFFSET(宣告利率!$V$2,B20,0,1,3)))) -> 2855620 | P20: =IF(B20="","",F20+L20) -> 2370304 | Q20: =IF(B20="","",IF(C20=109,0,OFFSET(宣告利率!$AB$2,B20,0)+OFFSET(宣告利率!$AC$2,B20,0))) -> 2370400 | R20: =IF(B20="","",P20+IF(ZDIVOPT02=CSWD,M20,0)+IF(ZDIVOPT02=DVAC,N20,0)) -> 2370304 | S20: =IF(C20=109,0,IF(B20="","",Q20+IF(ZDIVOPT02=CSWD,M20,0)+IF(ZDIVOPT02=DVAC,N20,0))) -> 2370400 | T20: =FYPremium -> 2655727 | U20: =IF(B20="","",OFFSET(宣告利率!$Y$2,B20,0)) -> 2505793.8 | V20: =IF(B20="","",P20+N20) -> 2370304 | W20: =IF(B20="","",V20/D20) -> 0.89252547 | X20: =IF(B20="","",IF(C20=109,0,Q20+N20)) -> 2370400 | Y20: =IF(B20="","",IF(OR(B20<PayYear,C20=109),"-",X20/D20)) -> 0.89256162 | Z20: =IF(B20="","",O20/D20) -> 1.0752687 | AA20: =AND(INDIRECT("B"&ROW())>0,MOD(INDIRECT("B"&ROW()),5)=0) -> FALSE
B21: =IF(B20="","",IF(C20=險種基本資料!$B$21,"",B20+1)) -> 2 | C21: =IF(B21="","",Age+B21-1) -> 72 | D21: =IF(B21="","",OFFSET(宣告利率!$I$2,B21,0)) -> 2655727 | E21: =IF(B21="","",OFFSET(宣告利率!$M$2,B21,0)+OFFSET(宣告利率!$K$2,B21,0)) -> 2542442 | F21: =IF(B21="","",OFFSET(宣告利率!$L$2,B21,0)+OFFSET(宣告利率!$K$2,B21,0)) -> 2339210 | G21: =IF(B21="","",OFFSET(宣告利率!$J$2,B21,0)) -> 2855620 | H21: =IF(B21="","",OFFSET(宣告利率!$G$2,B21,0)) -> 67822 | I21: =IF(B21="","",IF(C21<16,0,IF(C21=16,OFFSET(宣告利率!$O$2,B21-1,0),0)+OFFSET(宣告利率!$O$2,B21,0))) -> 98751 | J21: =IF(B21="","",IF(C21<16,0,OFFSET(宣告利率!$P$2,B21,0))) -> 195000 | K21: =IF(B21="","",IF(C21<16,OFFSET(宣告利率!$N$2,B21,0)+OFFSET(宣告利率!$U$2,B21,0),OFFSET(宣告利率!$Q$2,B21,0)+OFFSET(宣告利率!$U$2,B21,0))) -> 133926 | L21: =IF(B21="","",IF(C21<16,OFFSET(宣告利率!$N$2,B21,0),OFFSET(宣告利率!$Q$2,B21,0)+OFFSET(宣告利率!$U$2,B21,0))) -> 133926 | M21: =IF(B21="","",IF(OR(ZDIVOPT02=CSWD,ZDIVOPT02=DVAC),OFFSET(宣告利率!$R$2,B21,0),0)) -> 0 | N21: =IF(B21="","",IF(ZDIVOPT02=CSWD,OFFSET(宣告利率!$S$2,B21,0),IF(ZDIVOPT02=DVAC,OFFSET(宣告利率!$T$2,B21,0),0))) -> 0 | O21: =IF(B21="","",IF(C21<0,0,OFFSET(宣告利率!$J$2,B21,0)+MAX(OFFSET(宣告利率!$V$2,B21,0,1,3)))) -> 2929866 | P21: =IF(B21="","",F21+L21) -> 2473136 | Q21: =IF(B21="","",IF(C21=109,0,OFFSET(宣告利率!$AB$2,B21,0)+OFFSET(宣告利率!$AC$2,B21,0))) -> 2650932 | R21: =IF(B21="","",P21+IF(ZDIVOPT02=CSWD,M21,0)+IF(ZDIVOPT02=DVAC,N21,0)) -> 2473136 | S21: =IF(C21=109,0,IF(B21="","",Q21+IF(ZDIVOPT02=CSWD,M21,0)+IF(ZDIVOPT02=DVAC,N21,0))) -> 2650932 | T21: =IF(B21="","",FYPremium+(MIN(PayYear,B21)-1)*CYPremium) -> 2655727 | U21: =IF(B21="","",OFFSET(宣告利率!$Y$2,B21,0)) -> 2608546.1 | V21: =IF(B21="","",P21+N21) -> 2473136 | W21: =IF(B21="","",V21/D21) -> 0.93124632 | X21: =IF(B21="","",IF(C21=109,0,Q21+N21)) -> 2650932 | Y21: =IF(B21="","",IF(OR(B21<PayYear,C21=109),"-",X21/D21)) -> 0.99819447 | Z21: =IF(B21="","",O21/D21) -> 1.1032256 | AA21: =AND(INDIRECT("B"&ROW())>0,MOD(INDIRECT("B"&ROW()),5)=0) -> FALSE
B22: =IF(B21="","",IF(C21=險種基本資料!$B$21,"",B21+1)) -> 3 | C22: =IF(B22="","",Age+B22-1) -> 73 | D22: =IF(B22="","",OFFSET(宣告利率!$I$2,B22,0)) -> 2655727 | E22: =IF(B22="","",OFFSET(宣告利率!$M$2,B22,0)+OFFSET(宣告利率!$K$2,B22,0)) -> 2579831 | F22: =IF(B22="","",OFFSET(宣告利率!$L$2,B22,0)+OFFSET(宣告利率!$K$2,B22,0)) -> 2553918 | G22: =IF(B22="","",OFFSET(宣告利率!$J$2,B22,0)) -> 2855620 | H22: =IF(B22="","",OFFSET(宣告利率!$G$2,B22,0)) -> 70609 | I22: =IF(B22="","",IF(C22<16,0,IF(C22=16,OFFSET(宣告利率!$O$2,B22-1,0),0)+OFFSET(宣告利率!$O$2,B22,0))) -> 101319 | J22: =IF(B22="","",IF(C22<16,0,OFFSET(宣告利率!$P$2,B22,0))) -> 296319 | K22: =IF(B22="","",IF(C22<16,OFFSET(宣告利率!$N$2,B22,0)+OFFSET(宣告利率!$U$2,B22,0),OFFSET(宣告利率!$Q$2,B22,0)+OFFSET(宣告利率!$U$2,B22,0))) -> 206505 | L22: =IF(B22="","",IF(C22<16,OFFSET(宣告利率!$N$2,B22,0),OFFSET(宣告利率!$Q$2,B22,0)+OFFSET(宣告利率!$U$2,B22,0))) -> 206505 | M22: =IF(B22="","",IF(OR(ZDIVOPT02=CSWD,ZDIVOPT02=DVAC),OFFSET(宣告利率!$R$2,B22,0),0)) -> 0 | N22: =IF(B22="","",IF(ZDIVOPT02=CSWD,OFFSET(宣告利率!$S$2,B22,0),IF(ZDIVOPT02=DVAC,OFFSET(宣告利率!$T$2,B22,0),0))) -> 0 | O22: =IF(B22="","",IF(C22<0,0,OFFSET(宣告利率!$J$2,B22,0)+MAX(OFFSET(宣告利率!$V$2,B22,0,1,3)))) -> 3006043 | P22: =IF(B22="","",F22+L22) -> 2760423 | Q22: =IF(B22="","",IF(C22=109,0,OFFSET(宣告利率!$AB$2,B22,0)+OFFSET(宣告利率!$AC$2,B22,0))) -> 2760534 | R22: =IF(B22="","",P22+IF(ZDIVOPT02=CSWD,M22,0)+IF(ZDIVOPT02=DVAC,N22,0)) -> 2760423 | S22: =IF(C22=109,0,IF(B22="","",Q22+IF(ZDIVOPT02=CSWD,M22,0)+IF(ZDIVOPT02=DVAC,N22,0))) -> 2760534 | T22: =IF(B22="","",FYPremium+(MIN(PayYear,B22)-1)*CYPremium) -> 2655727 | U22: =IF(B22="","",OFFSET(宣告利率!$Y$2,B22,0)) -> 2715726.6 | V22: =IF(B22="","",P22+N22) -> 2760423 | W22: =IF(B22="","",V22/D22) -> 1.0394227 | X22: =IF(B22="","",IF(C22=109,0,Q22+N22)) -> 2760534 | Y22: =IF(B22="","",IF(OR(B22<PayYear,C22=109),"-",X22/D22)) -> 1.0394645 | Z22: =IF(B22="","",O22/D22) -> 1.1319096 | AA22: =AND(INDIRECT("B"&ROW())>0,MOD(INDIRECT("B"&ROW()),5)=0) -> FALSE
B23: =IF(B22="","",IF(C22=險種基本資料!$B$21,"",B22+1)) -> 4 | C23: =IF(B23="","",Age+B23-1) -> 74 | D23: =IF(B23="","",OFFSET(宣告利率!$I$2,B23,0)) -> 2655727 | E23: =IF(B23="","",OFFSET(宣告利率!$M$2,B23,0)+OFFSET(宣告利率!$K$2,B23,0)) -> 2617960 | F23: =IF(B23="","",OFFSET(宣告利率!$L$2,B23,0)+OFFSET(宣告利率!$K$2,B23,0)) -> 2591677 | G23: =IF(B23="","",OFFSET(宣告利率!$J$2,B23,0)) -> 2855620 | H23: =IF(B23="","",OFFSET(宣告利率!$G$2,B23,0)) -> 73515 | I23: =IF(B23="","",IF(C23<16,0,IF(C23=16,OFFSET(宣告利率!$O$2,B23-1,0),0)+OFFSET(宣告利率!$O$2,B23,0))) -> 103952 | J23: =IF(B23="","",IF(C23<16,0,OFFSET(宣告利率!$P$2,B23,0))) -> 400271 | K23: =IF(B23="","",IF(C23<16,OFFSET(宣告利率!$N$2,B23,0)+OFFSET(宣告利率!$U$2,B23,0),OFFSET(宣告利率!$Q$2,B23,0)+OFFSET(宣告利率!$U$2,B23,0))) -> 283072 | L23: =IF(B23="","",IF(C23<16,OFFSET(宣告利率!$N$2,B23,0),OFFSET(宣告利率!$Q$2,B23,0)+OFFSET(宣告利率!$U$2,B23,0))) -> 283072 | M23: =IF(B23="","",IF(OR(ZDIVOPT02=CSWD,ZDIVOPT02=DVAC),OFFSET(宣告利率!$R$2,B23,0),0)) -> 0 | N23: =IF(B23="","",IF(ZDIVOPT02=CSWD,OFFSET(宣告利率!$S$2,B23,0),IF(ZDIVOPT02=DVAC,OFFSET(宣告利率!$T$2,B23,0),0))) -> 0 | O23: =IF(B23="","",IF(C23<0,0,OFFSET(宣告利率!$J$2,B23,0)+MAX(OFFSET(宣告利率!$V$2,B23,0,1,3)))) -> 3084200 | P23: =IF(B23="","",F23+L23) -> 2874749 | Q23: =IF(B23="","",IF(C23=109,0,OFFSET(宣告利率!$AB$2,B23,0)+OFFSET(宣告利率!$AC$2,B23,0))) -> 2874793 | R23: =IF(B23="","",P23+IF(ZDIVOPT02=CSWD,M23,0)+IF(ZDIVOPT02=DVAC,N23,0)) -> 2874749 | S23: =IF(C23=109,0,IF(B23="","",Q23+IF(ZDIVOPT02=CSWD,M23,0)+IF(ZDIVOPT02=DVAC,N23,0))) -> 2874793 | T23: =IF(B23="","",FYPremium+(MIN(PayYear,B23)-1)*CYPremium) -> 2655727 | U23: =IF(B23="","",OFFSET(宣告利率!$Y$2,B23,0)) -> 2827517.1 | V23: =IF(B23="","",P23+N23) -> 2874749 | W23: =IF(B23="","",V23/D23) -> 1.0824716 | X23: =IF(B23="","",IF(C23=109,0,Q23+N23)) -> 2874793 | Y23: =IF(B23="","",IF(OR(B23<PayYear,C23=109),"-",X23/D23)) -> 1.0824881 | Z23: =IF(B23="","",O23/D23) -> 1.1613392 | AA23: =AND(INDIRECT("B"&ROW())>0,MOD(INDIRECT("B"&ROW()),5)=0) -> FALSE
B24: =IF(B23="","",IF(C23=險種基本資料!$B$21,"",B23+1)) -> 5 | C24: =IF(B24="","",Age+B24-1) -> 75 | D24: =IF(B24="","",OFFSET(宣告利率!$I$2,B24,0)) -> 2655727 | E24: =IF(B24="","",OFFSET(宣告利率!$M$2,B24,0)+OFFSET(宣告利率!$K$2,B24,0)) -> 2632398 | F24: =IF(B24="","",OFFSET(宣告利率!$L$2,B24,0)+OFFSET(宣告利率!$K$2,B24,0)) -> 2606114 | G24: =IF(B24="","",OFFSET(宣告利率!$J$2,B24,0)) -> 3701867 | H24: =IF(B24="","",OFFSET(宣告利率!$G$2,B24,0)) -> 75843 | I24: =IF(B24="","",IF(C24<16,0,IF(C24=16,OFFSET(宣告利率!$O$2,B24-1,0),0)+OFFSET(宣告利率!$O$2,B24,0))) -> 106656 | J24: =IF(B24="","",IF(C24<16,0,OFFSET(宣告利率!$P$2,B24,0))) -> 506927 | K24: =IF(B24="","",IF(C24<16,OFFSET(宣告利率!$N$2,B24,0)+OFFSET(宣告利率!$U$2,B24,0),OFFSET(宣告利率!$Q$2,B24,0)+OFFSET(宣告利率!$U$2,B24,0))) -> 360476 | L24: =IF(B24="","",IF(C24<16,OFFSET(宣告利率!$N$2,B24,0),OFFSET(宣告利率!$Q$2,B24,0)+OFFSET(宣告利率!$U$2,B24,0))) -> 360476 | M24: =IF(B24="","",IF(OR(ZDIVOPT02=CSWD,ZDIVOPT02=DVAC),OFFSET(宣告利率!$R$2,B24,0),0)) -> 0 | N24: =IF(B24="","",IF(ZDIVOPT02=CSWD,OFFSET(宣告利率!$S$2,B24,0),IF(ZDIVOPT02=DVAC,OFFSET(宣告利率!$T$2,B24,0),0))) -> 0 | O24: =IF(B24="","",IF(C24<0,0,OFFSET(宣告利率!$J$2,B24,0)+MAX(OFFSET(宣告利率!$V$2,B24,0,1,3)))) -> 4102138 | P24: =IF(B24="","",F24+L24) -> 2966590 | Q24: =IF(B24="","",IF(C24=109,0,OFFSET(宣告利率!$AB$2,B24,0)+OFFSET(宣告利率!$AC$2,B24,0))) -> 2966628 | R24: =IF(B24="","",P24+IF(ZDIVOPT02=CSWD,M24,0)+IF(ZDIVOPT02=DVAC,N24,0)) -> 2966590 | S24: =IF(C24=109,0,IF(B24="","",Q24+IF(ZDIVOPT02=CSWD,M24,0)+IF(ZDIVOPT02=DVAC,N24,0))) -> 2966628 | T24: =IF(B24="","",FYPremium+(MIN(PayYear,B24)-1)*CYPremium) -> 2655727 | U24: =IF(B24="","",OFFSET(宣告利率!$Y$2,B24,0)) -> 2917030.3 | V24: =IF(B24="","",P24+N24) -> 2966590 | W24: =IF(B24="","",V24/D24) -> 1.1170538 | X24: =IF(B24="","",IF(C24=109,0,Q24+N24)) -> 2966628 | Y24: =IF(B24="","",IF(OR(B24<PayYear,C24=109),"-",X24/D24)) -> 1.1170681 | Z24: =IF(B24="","",O24/D24) -> 1.5446384 | AA24: =AND(INDIRECT("B"&ROW())>0,MOD(INDIRECT("B"&ROW()),5)=0) -> TRUE
B25: =IF(B24="","",IF(C24=險種基本資料!$B$21,"",B24+1)) -> 6 | C25: =IF(B25="","",Age+B25-1) -> 76 | D25: =IF(B25="","",OFFSET(宣告利率!$I$2,B25,0)) -> 2655727 | E25: =IF(B25="","",OFFSET(宣告利率!$M$2,B25,0)+OFFSET(宣告利率!$K$2,B25,0)) -> 2644614 | F25: =IF(B25="","",OFFSET(宣告利率!$L$2,B25,0)+OFFSET(宣告利率!$K$2,B25,0)) -> 2618331 | G25: =IF(B25="","",OFFSET(宣告利率!$J$2,B25,0)) -> 3701867 | H25: =IF(B25="","",OFFSET(宣告利率!$G$2,B25,0)) -> 78176 | I25: =IF(B25="","",IF(C25<16,0,IF(C25=16,OFFSET(宣告利率!$O$2,B25-1,0),0)+OFFSET(宣告利率!$O$2,B25,0))) -> 109429 | J25: =IF(B25="","",IF(C25<16,0,OFFSET(宣告利率!$P$2,B25,0))) -> 616356 | K25: =IF(B25="","",IF(C25<16,OFFSET(宣告利率!$N$2,B25,0)+OFFSET(宣告利率!$U$2,B25,0),OFFSET(宣告利率!$Q$2,B25,0)+OFFSET(宣告利率!$U$2,B25,0))) -> 440325 | L25: =IF(B25="","",IF(C25<16,OFFSET(宣告利率!$N$2,B25,0),OFFSET(宣告利率!$Q$2,B25,0)+OFFSET(宣告利率!$U$2,B25,0))) -> 440325 | M25: =IF(B25="","",IF(OR(ZDIVOPT02=CSWD,ZDIVOPT02=DVAC),OFFSET(宣告利率!$R$2,B25,0),0)) -> 0 | N25: =IF(B25="","",IF(ZDIVOPT02=CSWD,OFFSET(宣告利率!$S$2,B25,0),IF(ZDIVOPT02=DVAC,OFFSET(宣告利率!$T$2,B25,0),0))) -> 0 | O25: =IF(B25="","",IF(C25<0,0,OFFSET(宣告利率!$J$2,B25,0)+MAX(OFFSET(宣告利率!$V$2,B25,0,1,3)))) -> 4208794 | P25: =IF(B25="","",F25+L25) -> 3058656 | Q25: =IF(B25="","",IF(C25=109,0,OFFSET(宣告利率!$AB$2,B25,0)+OFFSET(宣告利率!$AC$2,B25,0))) -> 3084969 | R25: =IF(B25="","",P25+IF(ZDIVOPT02=CSWD,M25,0)+IF(ZDIVOPT02=DVAC,N25,0)) -> 3058656 | S25: =IF(C25=109,0,IF(B25="","",Q25+IF(ZDIVOPT02=CSWD,M25,0)+IF(ZDIVOPT02=DVAC,N25,0))) -> 3084969 | T25: =IF(B25="","",FYPremium+(MIN(PayYear,B25)-1)*CYPremium) -> 2655727 | U25: =IF(B25="","",OFFSET(宣告利率!$Y$2,B25,0)) -> 3006762.4 | V25: =IF(B25="","",P25+N25) -> 3058656 | W25: =IF(B25="","",V25/D25) -> 1.1517208 | X25: =IF(B25="","",IF(C25=109,0,Q25+N25)) -> 3084969 | Y25: =IF(B25="","",IF(OR(B25<PayYear,C25=109),"-",X25/D25)) -> 1.1616288 | Z25: =IF(B25="","",O25/D25) -> 1.5847992 | AA25: =AND(INDIRECT("B"&ROW())>0,MOD(INDIRECT("B"&ROW()),5)=0) -> FALSE
B26: =IF(B25="","",IF(C25=險種基本資料!$B$21,"",B25+1)) -> 7 | C26: =IF(B26="","",Age+B26-1) -> 77 | D26: =IF(B26="","",OFFSET(宣告利率!$I$2,B26,0)) -> 2655727 | E26: =IF(B26="","",OFFSET(宣告利率!$M$2,B26,0)+OFFSET(宣告利率!$K$2,B26,0)) -> 2654239 | F26: =IF(B26="","",OFFSET(宣告利率!$L$2,B26,0)+OFFSET(宣告利率!$K$2,B26,0)) -> 2654239 | G26: =IF(B26="","",OFFSET(宣告利率!$J$2,B26,0)) -> 3701867 | H26: =IF(B26="","",OFFSET(宣告利率!$G$2,B26,0)) -> 80500 | I26: =IF(B26="","",IF(C26<16,0,IF(C26=16,OFFSET(宣告利率!$O$2,B26-1,0),0)+OFFSET(宣告利率!$O$2,B26,0))) -> 112273 | J26: =IF(B26="","",IF(C26<16,0,OFFSET(宣告利率!$P$2,B26,0))) -> 728629 | K26: =IF(B26="","",IF(C26<16,OFFSET(宣告利率!$N$2,B26,0)+OFFSET(宣告利率!$U$2,B26,0),OFFSET(宣告利率!$Q$2,B26,0)+OFFSET(宣告利率!$U$2,B26,0))) -> 522427 | L26: =IF(B26="","",IF(C26<16,OFFSET(宣告利率!$N$2,B26,0),OFFSET(宣告利率!$Q$2,B26,0)+OFFSET(宣告利率!$U$2,B26,0))) -> 522427 | M26: =IF(B26="","",IF(OR(ZDIVOPT02=CSWD,ZDIVOPT02=DVAC),OFFSET(宣告利率!$R$2,B26,0),0)) -> 0 | N26: =IF(B26="","",IF(ZDIVOPT02=CSWD,OFFSET(宣告利率!$S$2,B26,0),IF(ZDIVOPT02=DVAC,OFFSET(宣告利率!$T$2,B26,0),0))) -> 0 | O26: =IF(B26="","",IF(C26<0,0,OFFSET(宣告利率!$J$2,B26,0)+MAX(OFFSET(宣告利率!$V$2,B26,0,1,3)))) -> 4318223 | P26: =IF(B26="","",F26+L26) -> 3176666 | Q26: =IF(B26="","",IF(C26=109,0,OFFSET(宣告利率!$AB$2,B26,0)+OFFSET(宣告利率!$AC$2,B26,0))) -> 3176686 | R26: =IF(B26="","",P26+IF(ZDIVOPT02=CSWD,M26,0)+IF(ZDIVOPT02=DVAC,N26,0)) -> 3176666 | S26: =IF(C26=109,0,IF(B26="","",Q26+IF(ZDIVOPT02=CSWD,M26,0)+IF(ZDIVOPT02=DVAC,N26,0))) -> 3176686 | T26: =IF(B26="","",FYPremium+(MIN(PayYear,B26)-1)*CYPremium) -> 2655727 | U26: =IF(B26="","",OFFSET(宣告利率!$Y$2,B26,0)) -> 3096165.9 | V26: =IF(B26="","",P26+N26) -> 3176666 | W26: =IF(B26="","",V26/D26) -> 1.1961568 | X26: =IF(B26="","",IF(C26=109,0,Q26+N26)) -> 3176686 | Y26: =IF(B26="","",IF(OR(B26<PayYear,C26=109),"-",X26/D26)) -> 1.1961644 | Z26: =IF(B26="","",O26/D26) -> 1.6260041 | AA26: =AND(INDIRECT("B"&ROW())>0,MOD(INDIRECT("B"&ROW()),5)=0) -> FALSE
B27: =IF(B26="","",IF(C26=險種基本資料!$B$21,"",B26+1)) -> 8 | C27: =IF(B27="","",Age+B27-1) -> 78 | D27: =IF(B27="","",OFFSET(宣告利率!$I$2,B27,0)) -> 2655727 | E27: =IF(B27="","",OFFSET(宣告利率!$M$2,B27,0)+OFFSET(宣告利率!$K$2,B27,0)) -> 2660532 | F27: =IF(B27="","",OFFSET(宣告利率!$L$2,B27,0)+OFFSET(宣告利率!$K$2,B27,0)) -> 2660532 | G27: =IF(B27="","",OFFSET(宣告利率!$J$2,B27,0)) -> 3701867 | H27: =IF(B27="","",OFFSET(宣告利率!$G$2,B27,0)) -> 82789 | I27: =IF(B27="","",IF(C27<16,0,IF(C27=16,OFFSET(宣告利率!$O$2,B27-1,0),0)+OFFSET(宣告利率!$O$2,B27,0))) -> 115193 | J27: =IF(B27="","",IF(C27<16,0,OFFSET(宣告利率!$P$2,B27,0))) -> 843822 | K27: =IF(B27="","",IF(C27<16,OFFSET(宣告利率!$N$2,B27,0)+OFFSET(宣告利率!$U$2,B27,0),OFFSET(宣告利率!$Q$2,B27,0)+OFFSET(宣告利率!$U$2,B27,0))) -> 606455 | L27: =IF(B27="","",IF(C27<16,OFFSET(宣告利率!$N$2,B27,0),OFFSET(宣告利率!$Q$2,B27,0)+OFFSET(宣告利率!$U$2,B27,0))) -> 606455 | M27: =IF(B27="","",IF(OR(ZDIVOPT02=CSWD,ZDIVOPT02=DVAC),OFFSET(宣告利率!$R$2,B27,0),0)) -> 0 | N27: =IF(B27="","",IF(ZDIVOPT02=CSWD,OFFSET(宣告利率!$S$2,B27,0),IF(ZDIVOPT02=DVAC,OFFSET(宣告利率!$T$2,B27,0),0))) -> 0 | O27: =IF(B27="","",IF(C27<0,0,OFFSET(宣告利率!$J$2,B27,0)+MAX(OFFSET(宣告利率!$V$2,B27,0,1,3)))) -> 4430496 | P27: =IF(B27="","",F27+L27) -> 3266987 | Q27: =IF(B27="","",IF(C27=109,0,OFFSET(宣告利率!$AB$2,B27,0)+OFFSET(宣告利率!$AC$2,B27,0))) -> 3266995 | R27: =IF(B27="","",P27+IF(ZDIVOPT02=CSWD,M27,0)+IF(ZDIVOPT02=DVAC,N27,0)) -> 3266987 | S27: =IF(C27=109,0,IF(B27="","",Q27+IF(ZDIVOPT02=CSWD,M27,0)+IF(ZDIVOPT02=DVAC,N27,0))) -> 3266995 | T27: =IF(B27="","",FYPremium+(MIN(PayYear,B27)-1)*CYPremium) -> 2655727 | U27: =IF(B27="","",OFFSET(宣告利率!$Y$2,B27,0)) -> 3184197.5 | V27: =IF(B27="","",P27+N27) -> 3266987 | W27: =IF(B27="","",V27/D27) -> 1.2301667 | X27: =IF(B27="","",IF(C27=109,0,Q27+N27)) -> 3266995 | Y27: =IF(B27="","",IF(OR(B27<PayYear,C27=109),"-",X27/D27)) -> 1.2301697 | Z27: =IF(B27="","",O27/D27) -> 1.6682799 | AA27: =AND(INDIRECT("B"&ROW())>0,MOD(INDIRECT("B"&ROW()),5)=0) -> FALSE
B28: =IF(B27="","",IF(C27=險種基本資料!$B$21,"",B27+1)) -> 9 | C28: =IF(B28="","",Age+B28-1) -> 79 | D28: =IF(B28="","",OFFSET(宣告利率!$I$2,B28,0)) -> 2655727 | E28: =IF(B28="","",OFFSET(宣告利率!$M$2,B28,0)+OFFSET(宣告利率!$K$2,B28,0)) -> 2663123 | F28: =IF(B28="","",OFFSET(宣告利率!$L$2,B28,0)+OFFSET(宣告利率!$K$2,B28,0)) -> 2663123 | G28: =IF(B28="","",OFFSET(宣告利率!$J$2,B28,0)) -> 3701867 | H28: =IF(B28="","",OFFSET(宣告利率!$G$2,B28,0)) -> 85024 | I28: =IF(B28="","",IF(C28<16,0,IF(C28=16,OFFSET(宣告利率!$O$2,B28-1,0),0)+OFFSET(宣告利率!$O$2,B28,0))) -> 118187 | J28: =IF(B28="","",IF(C28<16,0,OFFSET(宣告利率!$P$2,B28,0))) -> 962009 | K28: =IF(B28="","",IF(C28<16,OFFSET(宣告利率!$N$2,B28,0)+OFFSET(宣告利率!$U$2,B28,0),OFFSET(宣告利率!$Q$2,B28,0)+OFFSET(宣告利率!$U$2,B28,0))) -> 692069 | L28: =IF(B28="","",IF(C28<16,OFFSET(宣告利率!$N$2,B28,0),OFFSET(宣告利率!$Q$2,B28,0)+OFFSET(宣告利率!$U$2,B28,0))) -> 692069 | M28: =IF(B28="","",IF(OR(ZDIVOPT02=CSWD,ZDIVOPT02=DVAC),OFFSET(宣告利率!$R$2,B28,0),0)) -> 0 | N28: =IF(B28="","",IF(ZDIVOPT02=CSWD,OFFSET(宣告利率!$S$2,B28,0),IF(ZDIVOPT02=DVAC,OFFSET(宣告利率!$T$2,B28,0),0))) -> 0 | O28: =IF(B28="","",IF(C28<0,0,OFFSET(宣告利率!$J$2,B28,0)+MAX(OFFSET(宣告利率!$V$2,B28,0,1,3)))) -> 4545689 | P28: =IF(B28="","",F28+L28) -> 3355192 | Q28: =IF(B28="","",IF(C28=109,0,OFFSET(宣告利率!$AB$2,B28,0)+OFFSET(宣告利率!$AC$2,B28,0))) -> 3355187 | R28: =IF(B28="","",P28+IF(ZDIVOPT02=CSWD,M28,0)+IF(ZDIVOPT02=DVAC,N28,0)) -> 3355192 | S28: =IF(C28=109,0,IF(B28="","",Q28+IF(ZDIVOPT02=CSWD,M28,0)+IF(ZDIVOPT02=DVAC,N28,0))) -> 3355187 | T28: =IF(B28="","",FYPremium+(MIN(PayYear,B28)-1)*CYPremium) -> 2655727 | U28: =IF(B28="","",OFFSET(宣告利率!$Y$2,B28,0)) -> 3270168.7 | V28: =IF(B28="","",P28+N28) -> 3355192 | W28: =IF(B28="","",V28/D28) -> 1.2633799 | X28: =IF(B28="","",IF(C28=109,0,Q28+N28)) -> 3355187 | Y28: =IF(B28="","",IF(OR(B28<PayYear,C28=109),"-",X28/D28)) -> 1.263378 | Z28: =IF(B28="","",O28/D28) -> 1.7116552 | AA28: =AND(INDIRECT("B"&ROW())>0,MOD(INDIRECT("B"&ROW()),5)=0) -> FALSE
B29: =IF(B28="","",IF(C28=險種基本資料!$B$21,"",B28+1)) -> 10 | C29: =IF(B29="","",Age+B29-1) -> 80 | D29: =IF(B29="","",OFFSET(宣告利率!$I$2,B29,0)) -> 2655727 | E29: =IF(B29="","",OFFSET(宣告利率!$M$2,B29,0)+OFFSET(宣告利率!$K$2,B29,0)) -> 2661642 | F29: =IF(B29="","",OFFSET(宣告利率!$L$2,B29,0)+OFFSET(宣告利率!$K$2,B29,0)) -> 2661642 | G29: =IF(B29="","",OFFSET(宣告利率!$J$2,B29,0)) -> 3701867 | H29: =IF(B29="","",OFFSET(宣告利率!$G$2,B29,0)) -> 87186 | I29: =IF(B29="","",IF(C29<16,0,IF(C29=16,OFFSET(宣告利率!$O$2,B29-1,0),0)+OFFSET(宣告利率!$O$2,B29,0))) -> 121260 | J29: =IF(B29="","",IF(C29<16,0,OFFSET(宣告利率!$P$2,B29,0))) -> 1083269 | K29: =IF(B29="","",IF(C29<16,OFFSET(宣告利率!$N$2,B29,0)+OFFSET(宣告利率!$U$2,B29,0),OFFSET(宣告利率!$Q$2,B29,0)+OFFSET(宣告利率!$U$2,B29,0))) -> 778870 | L29: =IF(B29="","",IF(C29<16,OFFSET(宣告利率!$N$2,B29,0),OFFSET(宣告利率!$Q$2,B29,0)+OFFSET(宣告利率!$U$2,B29,0))) -> 778870 | M29: =IF(B29="","",IF(OR(ZDIVOPT02=CSWD,ZDIVOPT02=DVAC),OFFSET(宣告利率!$R$2,B29,0),0)) -> 0 | N29: =IF(B29="","",IF(ZDIVOPT02=CSWD,OFFSET(宣告利率!$S$2,B29,0),IF(ZDIVOPT02=DVAC,OFFSET(宣告利率!$T$2,B29,0),0))) -> 0 | O29: =IF(B29="","",IF(C29<0,0,OFFSET(宣告利率!$J$2,B29,0)+MAX(OFFSET(宣告利率!$V$2,B29,0,1,3)))) -> 4663876 | P29: =IF(B29="","",F29+L29) -> 3440512 | Q29: =IF(B29="","",IF(C29=109,0,OFFSET(宣告利率!$AB$2,B29,0)+OFFSET(宣告利率!$AC$2,B29,0))) -> 3440505 | R29: =IF(B29="","",P29+IF(ZDIVOPT02=CSWD,M29,0)+IF(ZDIVOPT02=DVAC,N29,0)) -> 3440512 | S29: =IF(C29=109,0,IF(B29="","",Q29+IF(ZDIVOPT02=CSWD,M29,0)+IF(ZDIVOPT02=DVAC,N29,0))) -> 3440505 | T29: =IF(B29="","",FYPremium+(MIN(PayYear,B29)-1)*CYPremium) -> 2655727 | U29: =IF(B29="","",OFFSET(宣告利率!$Y$2,B29,0)) -> 3353326.8 | V29: =IF(B29="","",P29+N29) -> 3440512 | W29: =IF(B29="","",V29/D29) -> 1.2955067 | X29: =IF(B29="","",IF(C29=109,0,Q29+N29)) -> 3440505 | Y29: =IF(B29="","",IF(OR(B29<PayYear,C29=109),"-",X29/D29)) -> 1.295504 | Z29: =IF(B29="","",O29/D29) -> 1.7561579 | AA29: =AND(INDIRECT("B"&ROW())>0,MOD(INDIRECT("B"&ROW()),5)=0) -> TRUE
B30: =IF(B29="","",IF(C29=險種基本資料!$B$21,"",B29+1)) -> 11 | C30: =IF(B30="","",Age+B30-1) -> 81 | D30: =IF(B30="","",OFFSET(宣告利率!$I$2,B30,0)) -> 2655727 | E30: =IF(B30="","",OFFSET(宣告利率!$M$2,B30,0)+OFFSET(宣告利率!$K$2,B30,0)) -> 2659421 | F30: =IF(B30="","",OFFSET(宣告利率!$L$2,B30,0)+OFFSET(宣告利率!$K$2,B30,0)) -> 2659421 | G30: =IF(B30="","",OFFSET(宣告利率!$J$2,B30,0)) -> 3627830 | H30: =IF(B30="","",OFFSET(宣告利率!$G$2,B30,0)) -> 89379 | I30: =IF(B30="","",IF(C30<16,0,IF(C30=16,OFFSET(宣告利率!$O$2,B30-1,0),0)+OFFSET(宣告利率!$O$2,B30,0))) -> 124414 | J30: =IF(B30="","",IF(C30<16,0,OFFSET(宣告利率!$P$2,B30,0))) -> 1207683 | K30: =IF(B30="","",IF(C30<16,OFFSET(宣告利率!$N$2,B30,0)+OFFSET(宣告利率!$U$2,B30,0),OFFSET(宣告利率!$Q$2,B30,0)+OFFSET(宣告利率!$U$2,B30,0))) -> 867599 | L30: =IF(B30="","",IF(C30<16,OFFSET(宣告利率!$N$2,B30,0),OFFSET(宣告利率!$Q$2,B30,0)+OFFSET(宣告利率!$U$2,B30,0))) -> 867599 | M30: =IF(B30="","",IF(OR(ZDIVOPT02=CSWD,ZDIVOPT02=DVAC),OFFSET(宣告利率!$R$2,B30,0),0)) -> 0 | N30: =IF(B30="","",IF(ZDIVOPT02=CSWD,OFFSET(宣告利率!$S$2,B30,0),IF(ZDIVOPT02=DVAC,OFFSET(宣告利率!$T$2,B30,0),0))) -> 0 | O30: =IF(B30="","",IF(C30<0,0,OFFSET(宣告利率!$J$2,B30,0)+MAX(OFFSET(宣告利率!$V$2,B30,0,1,3)))) -> 4689434 | P30: =IF(B30="","",F30+L30) -> 3527020 | Q30: =IF(B30="","",IF(C30=109,0,OFFSET(宣告利率!$AB$2,B30,0)+OFFSET(宣告利率!$AC$2,B30,0))) -> 3527008 | R30: =IF(B30="","",P30+IF(ZDIVOPT02=CSWD,M30,0)+IF(ZDIVOPT02=DVAC,N30,0)) -> 3527020 | S30: =IF(C30=109,0,IF(B30="","",Q30+IF(ZDIVOPT02=CSWD,M30,0)+IF(ZDIVOPT02=DVAC,N30,0))) -> 3527008 | T30: =IF(B30="","",FYPremium+(MIN(PayYear,B30)-1)*CYPremium) -> 2655727 | U30: =IF(B30="","",OFFSET(宣告利率!$Y$2,B30,0)) -> 3437641.7 | V30: =IF(B30="","",P30+N30) -> 3527020 | W30: =IF(B30="","",V30/D30) -> 1.3280808 | X30: =IF(B30="","",IF(C30=109,0,Q30+N30)) -> 3527008 | Y30: =IF(B30="","",IF(OR(B30<PayYear,C30=109),"-",X30/D30)) -> 1.3280763 | Z30: =IF(B30="","",O30/D30) -> 1.7657816 | AA30: =AND(INDIRECT("B"&ROW())>0,MOD(INDIRECT("B"&ROW()),5)=0) -> FALSE
B31: =IF(B30="","",IF(C30=險種基本資料!$B$21,"",B30+1)) -> 12 | C31: =IF(B31="","",Age+B31-1) -> 82 | D31: =IF(B31="","",OFFSET(宣告利率!$I$2,B31,0)) -> 2655727 | E31: =IF(B31="","",OFFSET(宣告利率!$M$2,B31,0)+OFFSET(宣告利率!$K$2,B31,0)) -> 2656090 | F31: =IF(B31="","",OFFSET(宣告利率!$L$2,B31,0)+OFFSET(宣告利率!$K$2,B31,0)) -> 2656090 | G31: =IF(B31="","",OFFSET(宣告利率!$J$2,B31,0)) -> 3555273 | H31: =IF(B31="","",OFFSET(宣告利率!$G$2,B31,0)) -> 91588 | I31: =IF(B31="","",IF(C31<16,0,IF(C31=16,OFFSET(宣告利率!$O$2,B31-1,0),0)+OFFSET(宣告利率!$O$2,B31,0))) -> 127649 | J31: =IF(B31="","",IF(C31<16,0,OFFSET(宣告利率!$P$2,B31,0))) -> 1335332 | K31: =IF(B31="","",IF(C31<16,OFFSET(宣告利率!$N$2,B31,0)+OFFSET(宣告利率!$U$2,B31,0),OFFSET(宣告利率!$Q$2,B31,0)+OFFSET(宣告利率!$U$2,B31,0))) -> 958101 | L31: =IF(B31="","",IF(C31<16,OFFSET(宣告利率!$N$2,B31,0),OFFSET(宣告利率!$Q$2,B31,0)+OFFSET(宣告利率!$U$2,B31,0))) -> 958101 | M31: =IF(B31="","",IF(OR(ZDIVOPT02=CSWD,ZDIVOPT02=DVAC),OFFSET(宣告利率!$R$2,B31,0),0)) -> 0 | N31: =IF(B31="","",IF(ZDIVOPT02=CSWD,OFFSET(宣告利率!$S$2,B31,0),IF(ZDIVOPT02=DVAC,OFFSET(宣告利率!$T$2,B31,0),0))) -> 0 | O31: =IF(B31="","",IF(C31<0,0,OFFSET(宣告利率!$J$2,B31,0)+MAX(OFFSET(宣告利率!$V$2,B31,0,1,3)))) -> 4715132 | P31: =IF(B31="","",F31+L31) -> 3614191 | Q31: =IF(B31="","",IF(C31=109,0,OFFSET(宣告利率!$AB$2,B31,0)+OFFSET(宣告利率!$AC$2,B31,0))) -> 3614175 | R31: =IF(B31="","",P31+IF(ZDIVOPT02=CSWD,M31,0)+IF(ZDIVOPT02=DVAC,N31,0)) -> 3614191 | S31: =IF(C31=109,0,IF(B31="","",Q31+IF(ZDIVOPT02=CSWD,M31,0)+IF(ZDIVOPT02=DVAC,N31,0))) -> 3614175 | T31: =IF(B31="","",FYPremium+(MIN(PayYear,B31)-1)*CYPremium) -> 2655727 | U31: =IF(B31="","",OFFSET(宣告利率!$Y$2,B31,0)) -> 3522602.1 | V31: =IF(B31="","",P31+N31) -> 3614191 | W31: =IF(B31="","",V31/D31) -> 1.3609046 | X31: =IF(B31="","",IF(C31=109,0,Q31+N31)) -> 3614175 | Y31: =IF(B31="","",IF(OR(B31<PayYear,C31=109),"-",X31/D31)) -> 1.3608985 | Z31: =IF(B31="","",O31/D31) -> 1.7754581 | AA31: =AND(INDIRECT("B"&ROW())>0,MOD(INDIRECT("B"&ROW()),5)=0) -> FALSE
B32: =IF(B31="","",IF(C31=險種基本資料!$B$21,"",B31+1)) -> 13 | C32: =IF(B32="","",Age+B32-1) -> 83 | D32: =IF(B32="","",OFFSET(宣告利率!$I$2,B32,0)) -> 2655727 | E32: =IF(B32="","",OFFSET(宣告利率!$M$2,B32,0)+OFFSET(宣告利率!$K$2,B32,0)) -> 2652018 | F32: =IF(B32="","",OFFSET(宣告利率!$L$2,B32,0)+OFFSET(宣告利率!$K$2,B32,0)) -> 2652018 | G32: =IF(B32="","",OFFSET(宣告利率!$J$2,B32,0)) -> 3484197 | H32: =IF(B32="","",OFFSET(宣告利率!$G$2,B32,0)) -> 93825 | I32: =IF(B32="","",IF(C32<16,0,IF(C32=16,OFFSET(宣告利率!$O$2,B32-1,0),0)+OFFSET(宣告利率!$O$2,B32,0))) -> 130967 | J32: =IF(B32="","",IF(C32<16,0,OFFSET(宣告利率!$P$2,B32,0))) -> 1466299 | K32: =IF(B32="","",IF(C32<16,OFFSET(宣告利率!$N$2,B32,0)+OFFSET(宣告利率!$U$2,B32,0),OFFSET(宣告利率!$Q$2,B32,0)+OFFSET(宣告利率!$U$2,B32,0))) -> 1050457 | L32: =IF(B32="","",IF(C32<16,OFFSET(宣告利率!$N$2,B32,0),OFFSET(宣告利率!$Q$2,B32,0)+OFFSET(宣告利率!$U$2,B32,0))) -> 1050457 | M32: =IF(B32="","",IF(OR(ZDIVOPT02=CSWD,ZDIVOPT02=DVAC),OFFSET(宣告利率!$R$2,B32,0),0)) -> 0 | N32: =IF(B32="","",IF(ZDIVOPT02=CSWD,OFFSET(宣告利率!$S$2,B32,0),IF(ZDIVOPT02=DVAC,OFFSET(宣告利率!$T$2,B32,0),0))) -> 0 | O32: =IF(B32="","",IF(C32<0,0,OFFSET(宣告利率!$J$2,B32,0)+MAX(OFFSET(宣告利率!$V$2,B32,0,1,3)))) -> 4741011 | P32: =IF(B32="","",F32+L32) -> 3702475 | Q32: =IF(B32="","",IF(C32=109,0,OFFSET(宣告利率!$AB$2,B32,0)+OFFSET(宣告利率!$AC$2,B32,0))) -> 3702457 | R32: =IF(B32="","",P32+IF(ZDIVOPT02=CSWD,M32,0)+IF(ZDIVOPT02=DVAC,N32,0)) -> 3702475 | S32: =IF(C32=109,0,IF(B32="","",Q32+IF(ZDIVOPT02=CSWD,M32,0)+IF(ZDIVOPT02=DVAC,N32,0))) -> 3702457 | T32: =IF(B32="","",FYPremium+(MIN(PayYear,B32)-1)*CYPremium) -> 2655727 | U32: =IF(B32="","",OFFSET(宣告利率!$Y$2,B32,0)) -> 3608649.4 | V32: =IF(B32="","",P32+N32) -> 3702475 | W32: =IF(B32="","",V32/D32) -> 1.3941474 | X32: =IF(B32="","",IF(C32=109,0,Q32+N32)) -> 3702457 | Y32: =IF(B32="","",IF(OR(B32<PayYear,C32=109),"-",X32/D32)) -> 1.3941407 | Z32: =IF(B32="","",O32/D32) -> 1.7852027 | AA32: =AND(INDIRECT("B"&ROW())>0,MOD(INDIRECT("B"&ROW()),5)=0) -> FALSE
... B34: =IF(B33="","",IF(C33=險種基本資料!$B$21,"",B33+1)) -> 15 | C34: =IF(B34="","",Age+B34-1) -> 85 | D34: =IF(B34="","",OFFSET(宣告利率!$I$2,B34,0)) -> 2655727 | E34: =IF(B34="","",OFFSET(宣告利率!$M$2,B34,0)+OFFSET(宣告利率!$K$2,B34,0)) -> 2642763 | F34: =IF(B34="","",OFFSET(宣告利率!$L$2,B34,0)+OFFSET(宣告利率!$K$2,B34,0)) -> 2642763 | G34: =IF(B34="","",OFFSET(宣告利率!$J$2,B34,0)) -> 3346488 | H34: =IF(B34="","",OFFSET(宣告利率!$G$2,B34,0)) -> 98423 | I34: =IF(B34="","",IF(C34<16,0,IF(C34=16,OFFSET(宣告利率!$O$2,B34-1,0),0)+OFFSET(宣告利率!$O$2,B34,0))) -> 137867 | J34: =IF(B34="","",IF(C34<16,0,OFFSET(宣告利率!$P$2,B34,0))) -> 1738538 | K34: =IF(B34="","",IF(C34<16,OFFSET(宣告利率!$N$2,B34,0)+OFFSET(宣告利率!$U$2,B34,0),OFFSET(宣告利率!$Q$2,B34,0)+OFFSET(宣告利率!$U$2,B34,0))) -> 1241142 | L34: =IF(B34="","",IF(C34<16,OFFSET(宣告利率!$N$2,B34,0),OFFSET(宣告利率!$Q$2,B34,0)+OFFSET(宣告利率!$U$2,B34,0))) -> 1241142 | M34: =IF(B34="","",IF(OR(ZDIVOPT02=CSWD,ZDIVOPT02=DVAC),OFFSET(宣告利率!$R$2,B34,0),0)) -> 0 | N34: =IF(B34="","",IF(ZDIVOPT02=CSWD,OFFSET(宣告利率!$S$2,B34,0),IF(ZDIVOPT02=DVAC,OFFSET(宣告利率!$T$2,B34,0),0))) -> 0 | O34: =IF(B34="","",IF(C34<0,0,OFFSET(宣告利率!$J$2,B34,0)+MAX(OFFSET(宣告利率!$V$2,B34,0,1,3)))) -> 4793495 | P34: =IF(B34="","",F34+L34) -> 3883905 | Q34: =IF(B34="","",IF(C34=109,0,OFFSET(宣告利率!$AB$2,B34,0)+OFFSET(宣告利率!$AC$2,B34,0))) -> 3883886 | R34: =IF(B34="","",P34+IF(ZDIVOPT02=CSWD,M34,0)+IF(ZDIVOPT02=DVAC,N34,0)) -> 3883905 | S34: =IF(C34=109,0,IF(B34="","",Q34+IF(ZDIVOPT02=CSWD,M34,0)+IF(ZDIVOPT02=DVAC,N34,0))) -> 3883886 | T34: =IF(B34="","",FYPremium+(MIN(PayYear,B34)-1)*CYPremium) -> 2655727 | U34: =IF(B34="","",OFFSET(宣告利率!$Y$2,B34,0)) -> 3785481.9 | V34: =IF(B34="","",P34+N34) -> 3883905 | W34: =IF(B34="","",V34/D34) -> 1.462464 | X34: =IF(B34="","",IF(C34=109,0,Q34+N34)) -> 3883886 | Y34: =IF(B34="","",IF(OR(B34<PayYear,C34=109),"-",X34/D34)) -> 1.4624568 | Z34: =IF(B34="","",O34/D34) -> 1.8049653 | AA34: =AND(INDIRECT("B"&ROW())>0,MOD(INDIRECT("B"&ROW()),5)=0) -> TRUE
B35: =B17 -> 保單 年度 (末) | C35: =C17 -> 保險 年齡 | D35: =D17 -> 累積所繳保險費 (A) | E35: =E17 -> 基本保險金額對應之保單價值準備金 【含祝壽保險金】 | F35: =F17 -> 基本保險金額 對應之現金價值 【含祝壽保險金】 (B) | G35: =G17 -> 基本保險金額 對應之壽險保障 (身故保險金) | J35: =J17 -> 假設投保後未來各保單年度宣告利率為4.35% (下表為預估假設值) | R35: =R17 -> 年度末終止契約時合計可領取之金額(含增值回饋分享金) (F) | S35: =S17 -> 次年度期初終止契約時合計可領取之金額(含增值回饋分享金) (H)=(G) | T35: =T17 -> 累積 應繳保費 | U35: =U17 -> 期末保單價值準備金(含基本保險金額、累計增加保險金額) 【含祝壽保險金】 | V35: =V17 -> (E)+(F) | W35: =W17 -> ((E)+(F))/(A) | X35: =X17 -> (G)+(E) | Y35: =Y17 -> ((G)+(E))/(A) | Z35: =Z17 -> (I)/(A) | AA35: =AND(INDIRECT("B"&ROW())>0,MOD(INDIRECT("B"&ROW()),5)=0) -> #VALUE!
C36: =C18 -> 0 | D36: =D18 -> 0 | E36: =E18 -> 0 | F36: =F18 -> 0 | G36: =G18 -> 0 | H36: =H18 -> 增值回饋分享金 | I36: =I18 -> 選擇以繳清保險方式增加保險金額 | J36: =J18 -> 0 | ... Q36: =Q18 -> 0 | T36: =T18 -> 0 | U36: =U18 -> 0 | V36: =V18 -> 0 | W36: =W18 -> 0 | X36: =X18 -> 0 | Y36: =Y18 -> 0 | AA36: =AND(INDIRECT("B"&ROW())>0,MOD(INDIRECT("B"&ROW()),5)=0) -> FALSE
C37: =C19 -> 0 | D37: =D19 -> 0 | E37: =E19 -> 0 | F37: =F19 -> 0 | G37: =G19 -> 0 | H37: =H19 -> 0 | I37: =I19 -> 增額繳清保險金額 | J37: =J19 -> 累計增加 保險金額 | ... Q37: =Q19 -> 次年度期初 現金價值 (G) | T37: =T19 -> 0 | U37: =U19 -> 0 | V37: =V19 -> 0 | W37: =W19 -> 0 | X37: =X19 -> 0 | Y37: =Y19 -> 0 | AA37: =AND(INDIRECT("B"&ROW())>0,MOD(INDIRECT("B"&ROW()),5)=0) -> FALSE
B38: =IF(B34="","",IF(C34=險種基本資料!$B$21,"",B34+1)) -> 16 | C38: =IF(B38="","",Age+B38-1) -> 86 | D38: =IF(B38="","",OFFSET(宣告利率!$I$2,B38,0)) -> 2655727 | E38: =IF(B38="","",OFFSET(宣告利率!$M$2,B38,0)+OFFSET(宣告利率!$K$2,B38,0)) -> 2637950 | F38: =IF(B38="","",OFFSET(宣告利率!$L$2,B38,0)+OFFSET(宣告利率!$K$2,B38,0)) -> 2637950 | G38: =IF(B38="","",OFFSET(宣告利率!$J$2,B38,0)) -> 3279484 | H38: =IF(B38="","",OFFSET(宣告利率!$G$2,B38,0)) -> 100798 | I38: =IF(B38="","",IF(C38<16,0,IF(C38=16,OFFSET(宣告利率!$O$2,B38-1,0),0)+OFFSET(宣告利率!$O$2,B38,0))) -> 141451 | J38: =IF(B38="","",IF(C38<16,0,OFFSET(宣告利率!$P$2,B38,0))) -> 1879989 | K38: =IF(B38="","",IF(C38<16,OFFSET(宣告利率!$N$2,B38,0)+OFFSET(宣告利率!$U$2,B38,0),OFFSET(宣告利率!$Q$2,B38,0)+OFFSET(宣告利率!$U$2,B38,0))) -> 1339680 | L38: =IF(B38="","",IF(C38<16,OFFSET(宣告利率!$N$2,B38,0),OFFSET(宣告利率!$Q$2,B38,0)+OFFSET(宣告利率!$U$2,B38,0))) -> 1339680 | M38: =IF(B38="","",IF(OR(ZDIVOPT02=CSWD,ZDIVOPT02=DVAC),OFFSET(宣告利率!$R$2,B38,0),0)) -> 0 | N38: =IF(B38="","",IF(ZDIVOPT02=CSWD,OFFSET(宣告利率!$S$2,B38,0),IF(ZDIVOPT02=DVAC,OFFSET(宣告利率!$T$2,B38,0),0))) -> 0 | O38: =IF(B38="","",IF(C38<0,0,OFFSET(宣告利率!$J$2,B38,0)+MAX(OFFSET(宣告利率!$V$2,B38,0,1,3)))) -> 4819655 | P38: =IF(B38="","",F38+L38) -> 3977630 | Q38: =IF(B38="","",IF(C38=109,0,OFFSET(宣告利率!$AB$2,B38,0)+OFFSET(宣告利率!$AC$2,B38,0))) -> 3977610 | R38: =IF(B38="","",P38+IF(ZDIVOPT02=CSWD,M38,0)+IF(ZDIVOPT02=DVAC,N38,0)) -> 3977630 | S38: =IF(C38=109,0,IF(B38="","",Q38+IF(ZDIVOPT02=CSWD,M38,0)+IF(ZDIVOPT02=DVAC,N38,0))) -> 3977610 | T38: =IF(B38="","",FYPremium+(MIN(PayYear,B38)-1)*CYPremium) -> 2655727 | U38: =IF(B38="","",OFFSET(宣告利率!$Y$2,B38,0)) -> 3876832.6 | V38: =IF(B38="","",P38+N38) -> 3977630 | W38: =IF(B38="","",V38/D38) -> 1.4977556 | X38: =IF(B38="","",IF(C38=109,0,Q38+N38)) -> 3977610 | Y38: =IF(B38="","",IF(OR(B38<PayYear,C38=109),"-",X38/D38)) -> 1.4977481 | Z38: =IF(B38="","",O38/D38) -> 1.8148157 | AA38: =AND(INDIRECT("B"&ROW())>0,MOD(INDIRECT("B"&ROW()),5)=0) -> FALSE
